2020-07-11 23:08:42,369 INFO: Microblog Starting [in /Users/sadeliyi/Documents/Python Projects/microblog_app/app/__init__.py:44]
2020-07-11 23:08:50,126 ERROR: Exception on /edit_profile [GET] [in /Users/sadeliyi/Documents/Python Projects/microblog_app/venv/lib/python3.7/site-packages/flask/app.py:1892]
Traceback (most recent call last):
  File "/Users/sadeliyi/Documents/Python Projects/microblog_app/venv/lib/python3.7/site-packages/flask/app.py", line 2447, in wsgi_app
    response = self.full_dispatch_request()
  File "/Users/sadeliyi/Documents/Python Projects/microblog_app/venv/lib/python3.7/site-packages/flask/app.py", line 1952, in full_dispatch_request
    rv = self.handle_user_exception(e)
  File "/Users/sadeliyi/Documents/Python Projects/microblog_app/venv/lib/python3.7/site-packages/flask/app.py", line 1821, in handle_user_exception
    reraise(exc_type, exc_value, tb)
  File "/Users/sadeliyi/Documents/Python Projects/microblog_app/venv/lib/python3.7/site-packages/flask/_compat.py", line 39, in reraise
    raise value
  File "/Users/sadeliyi/Documents/Python Projects/microblog_app/venv/lib/python3.7/site-packages/flask/app.py", line 1950, in full_dispatch_request
    rv = self.dispatch_request()
  File "/Users/sadeliyi/Documents/Python Projects/microblog_app/venv/lib/python3.7/site-packages/flask/app.py", line 1936, in dispatch_request
    return self.view_functions[rule.endpoint](**req.view_args)
  File "/Users/sadeliyi/Documents/Python Projects/microblog_app/venv/lib/python3.7/site-packages/flask_login/utils.py", line 272, in decorated_view
    return func(*args, **kwargs)
  File "/Users/sadeliyi/Documents/Python Projects/microblog_app/app/routes.py", line 94, in edit_profile
    return render_template('edit_profile.html', form=form, title='Edit Profile')
  File "/Users/sadeliyi/Documents/Python Projects/microblog_app/venv/lib/python3.7/site-packages/flask/templating.py", line 140, in render_template
    ctx.app,
  File "/Users/sadeliyi/Documents/Python Projects/microblog_app/venv/lib/python3.7/site-packages/flask/templating.py", line 120, in _render
    rv = template.render(context)
  File "/Users/sadeliyi/Documents/Python Projects/microblog_app/venv/lib/python3.7/site-packages/jinja2/environment.py", line 1090, in render
    self.environment.handle_exception()
  File "/Users/sadeliyi/Documents/Python Projects/microblog_app/venv/lib/python3.7/site-packages/jinja2/environment.py", line 832, in handle_exception
    reraise(*rewrite_traceback_stack(source=source))
  File "/Users/sadeliyi/Documents/Python Projects/microblog_app/venv/lib/python3.7/site-packages/jinja2/_compat.py", line 28, in reraise
    raise value.with_traceback(tb)
  File "/Users/sadeliyi/Documents/Python Projects/microblog_app/app/templates/edit_profile.html", line 1, in top-level template code
    {% extends 'base.html' %}
  File "/Users/sadeliyi/Documents/Python Projects/microblog_app/app/templates/base.html", line 31, in top-level template code
    {% block content %}
  File "/Users/sadeliyi/Documents/Python Projects/microblog_app/app/templates/edit_profile.html", line 6, in block "content"
    {{ form.hidden_tag() }}
  File "/Users/sadeliyi/Documents/Python Projects/microblog_app/venv/lib/python3.7/site-packages/flask_wtf/form.py", line 134, in hidden_tag
    u'\n'.join(text_type(f) for f in hidden_fields(fields or self))
  File "/Users/sadeliyi/Documents/Python Projects/microblog_app/venv/lib/python3.7/site-packages/flask_wtf/form.py", line 134, in <genexpr>
    u'\n'.join(text_type(f) for f in hidden_fields(fields or self))
  File "/Users/sadeliyi/Documents/Python Projects/microblog_app/venv/lib/python3.7/site-packages/flask_wtf/form.py", line 124, in hidden_fields
    for f in fields:
  File "/Users/sadeliyi/Documents/Python Projects/microblog_app/venv/lib/python3.7/site-packages/wtforms/form.py", line 56, in __iter__
    return iter(itervalues(self._fields))
AttributeError: 'EditProfileForm' object has no attribute '_fields'
2020-07-11 23:08:59,299 ERROR: Exception on /edit_profile [GET] [in /Users/sadeliyi/Documents/Python Projects/microblog_app/venv/lib/python3.7/site-packages/flask/app.py:1892]
Traceback (most recent call last):
  File "/Users/sadeliyi/Documents/Python Projects/microblog_app/venv/lib/python3.7/site-packages/flask/app.py", line 2447, in wsgi_app
    response = self.full_dispatch_request()
  File "/Users/sadeliyi/Documents/Python Projects/microblog_app/venv/lib/python3.7/site-packages/flask/app.py", line 1952, in full_dispatch_request
    rv = self.handle_user_exception(e)
  File "/Users/sadeliyi/Documents/Python Projects/microblog_app/venv/lib/python3.7/site-packages/flask/app.py", line 1821, in handle_user_exception
    reraise(exc_type, exc_value, tb)
  File "/Users/sadeliyi/Documents/Python Projects/microblog_app/venv/lib/python3.7/site-packages/flask/_compat.py", line 39, in reraise
    raise value
  File "/Users/sadeliyi/Documents/Python Projects/microblog_app/venv/lib/python3.7/site-packages/flask/app.py", line 1950, in full_dispatch_request
    rv = self.dispatch_request()
  File "/Users/sadeliyi/Documents/Python Projects/microblog_app/venv/lib/python3.7/site-packages/flask/app.py", line 1936, in dispatch_request
    return self.view_functions[rule.endpoint](**req.view_args)
  File "/Users/sadeliyi/Documents/Python Projects/microblog_app/venv/lib/python3.7/site-packages/flask_login/utils.py", line 272, in decorated_view
    return func(*args, **kwargs)
  File "/Users/sadeliyi/Documents/Python Projects/microblog_app/app/routes.py", line 94, in edit_profile
    return render_template('edit_profile.html', form=form, title='Edit Profile')
  File "/Users/sadeliyi/Documents/Python Projects/microblog_app/venv/lib/python3.7/site-packages/flask/templating.py", line 140, in render_template
    ctx.app,
  File "/Users/sadeliyi/Documents/Python Projects/microblog_app/venv/lib/python3.7/site-packages/flask/templating.py", line 120, in _render
    rv = template.render(context)
  File "/Users/sadeliyi/Documents/Python Projects/microblog_app/venv/lib/python3.7/site-packages/jinja2/environment.py", line 1090, in render
    self.environment.handle_exception()
  File "/Users/sadeliyi/Documents/Python Projects/microblog_app/venv/lib/python3.7/site-packages/jinja2/environment.py", line 832, in handle_exception
    reraise(*rewrite_traceback_stack(source=source))
  File "/Users/sadeliyi/Documents/Python Projects/microblog_app/venv/lib/python3.7/site-packages/jinja2/_compat.py", line 28, in reraise
    raise value.with_traceback(tb)
  File "/Users/sadeliyi/Documents/Python Projects/microblog_app/app/templates/edit_profile.html", line 1, in top-level template code
    {% extends 'base.html' %}
  File "/Users/sadeliyi/Documents/Python Projects/microblog_app/app/templates/base.html", line 31, in top-level template code
    {% block content %}
  File "/Users/sadeliyi/Documents/Python Projects/microblog_app/app/templates/edit_profile.html", line 6, in block "content"
    {{ form.hidden_tag() }}
  File "/Users/sadeliyi/Documents/Python Projects/microblog_app/venv/lib/python3.7/site-packages/flask_wtf/form.py", line 134, in hidden_tag
    u'\n'.join(text_type(f) for f in hidden_fields(fields or self))
  File "/Users/sadeliyi/Documents/Python Projects/microblog_app/venv/lib/python3.7/site-packages/flask_wtf/form.py", line 134, in <genexpr>
    u'\n'.join(text_type(f) for f in hidden_fields(fields or self))
  File "/Users/sadeliyi/Documents/Python Projects/microblog_app/venv/lib/python3.7/site-packages/flask_wtf/form.py", line 124, in hidden_fields
    for f in fields:
  File "/Users/sadeliyi/Documents/Python Projects/microblog_app/venv/lib/python3.7/site-packages/wtforms/form.py", line 56, in __iter__
    return iter(itervalues(self._fields))
AttributeError: 'EditProfileForm' object has no attribute '_fields'
2020-07-11 23:09:13,219 ERROR: Exception on /edit_profile [GET] [in /Users/sadeliyi/Documents/Python Projects/microblog_app/venv/lib/python3.7/site-packages/flask/app.py:1892]
Traceback (most recent call last):
  File "/Users/sadeliyi/Documents/Python Projects/microblog_app/venv/lib/python3.7/site-packages/flask/app.py", line 2447, in wsgi_app
    response = self.full_dispatch_request()
  File "/Users/sadeliyi/Documents/Python Projects/microblog_app/venv/lib/python3.7/site-packages/flask/app.py", line 1952, in full_dispatch_request
    rv = self.handle_user_exception(e)
  File "/Users/sadeliyi/Documents/Python Projects/microblog_app/venv/lib/python3.7/site-packages/flask/app.py", line 1821, in handle_user_exception
    reraise(exc_type, exc_value, tb)
  File "/Users/sadeliyi/Documents/Python Projects/microblog_app/venv/lib/python3.7/site-packages/flask/_compat.py", line 39, in reraise
    raise value
  File "/Users/sadeliyi/Documents/Python Projects/microblog_app/venv/lib/python3.7/site-packages/flask/app.py", line 1950, in full_dispatch_request
    rv = self.dispatch_request()
  File "/Users/sadeliyi/Documents/Python Projects/microblog_app/venv/lib/python3.7/site-packages/flask/app.py", line 1936, in dispatch_request
    return self.view_functions[rule.endpoint](**req.view_args)
  File "/Users/sadeliyi/Documents/Python Projects/microblog_app/venv/lib/python3.7/site-packages/flask_login/utils.py", line 272, in decorated_view
    return func(*args, **kwargs)
  File "/Users/sadeliyi/Documents/Python Projects/microblog_app/app/routes.py", line 94, in edit_profile
    return render_template('edit_profile.html', form=form, title='Edit Profile')
  File "/Users/sadeliyi/Documents/Python Projects/microblog_app/venv/lib/python3.7/site-packages/flask/templating.py", line 140, in render_template
    ctx.app,
  File "/Users/sadeliyi/Documents/Python Projects/microblog_app/venv/lib/python3.7/site-packages/flask/templating.py", line 120, in _render
    rv = template.render(context)
  File "/Users/sadeliyi/Documents/Python Projects/microblog_app/venv/lib/python3.7/site-packages/jinja2/environment.py", line 1090, in render
    self.environment.handle_exception()
  File "/Users/sadeliyi/Documents/Python Projects/microblog_app/venv/lib/python3.7/site-packages/jinja2/environment.py", line 832, in handle_exception
    reraise(*rewrite_traceback_stack(source=source))
  File "/Users/sadeliyi/Documents/Python Projects/microblog_app/venv/lib/python3.7/site-packages/jinja2/_compat.py", line 28, in reraise
    raise value.with_traceback(tb)
  File "/Users/sadeliyi/Documents/Python Projects/microblog_app/app/templates/edit_profile.html", line 1, in top-level template code
    {% extends 'base.html' %}
  File "/Users/sadeliyi/Documents/Python Projects/microblog_app/app/templates/base.html", line 31, in top-level template code
    {% block content %}
  File "/Users/sadeliyi/Documents/Python Projects/microblog_app/app/templates/edit_profile.html", line 6, in block "content"
    {{ form.hidden_tag() }}
  File "/Users/sadeliyi/Documents/Python Projects/microblog_app/venv/lib/python3.7/site-packages/flask_wtf/form.py", line 134, in hidden_tag
    u'\n'.join(text_type(f) for f in hidden_fields(fields or self))
  File "/Users/sadeliyi/Documents/Python Projects/microblog_app/venv/lib/python3.7/site-packages/flask_wtf/form.py", line 134, in <genexpr>
    u'\n'.join(text_type(f) for f in hidden_fields(fields or self))
  File "/Users/sadeliyi/Documents/Python Projects/microblog_app/venv/lib/python3.7/site-packages/flask_wtf/form.py", line 124, in hidden_fields
    for f in fields:
  File "/Users/sadeliyi/Documents/Python Projects/microblog_app/venv/lib/python3.7/site-packages/wtforms/form.py", line 56, in __iter__
    return iter(itervalues(self._fields))
AttributeError: 'EditProfileForm' object has no attribute '_fields'
2020-07-11 23:12:41,348 INFO: Microblog Starting [in /Users/sadeliyi/Documents/Python Projects/microblog_app/app/__init__.py:44]
2020-07-11 23:20:26,059 INFO: Microblog Starting [in /Users/sadeliyi/Documents/Python Projects/microblog_app/app/__init__.py:44]
2020-07-13 10:30:13,709 INFO: Microblog Starting [in /Users/sadeliyi/Documents/Python Projects/microblog_app/app/__init__.py:44]
2020-07-13 10:30:21,661 INFO: Microblog Starting [in /Users/sadeliyi/Documents/Python Projects/microblog_app/app/__init__.py:44]
2020-07-14 18:52:54,159 INFO: Microblog Starting [in /Users/sadeliyi/Documents/Python Projects/microblog_app/app/__init__.py:44]
2020-07-14 18:53:05,269 INFO: Microblog Starting [in /Users/sadeliyi/Documents/Python Projects/microblog_app/app/__init__.py:44]
2020-07-14 18:53:56,154 INFO: Microblog Starting [in /Users/sadeliyi/Documents/Python Projects/microblog_app/app/__init__.py:44]
2020-07-14 18:58:23,867 INFO: Microblog Starting [in /Users/sadeliyi/Documents/Python Projects/microblog_app/app/__init__.py:44]
2020-07-14 20:21:41,637 INFO: Microblog Starting [in /Users/sadeliyi/Documents/Python Projects/microblog_app/app/__init__.py:44]
2020-07-15 02:31:59,084 INFO: Microblog Starting [in /Users/sadeliyi/Documents/Python Projects/microblog_app/app/__init__.py:44]
2020-07-15 02:33:40,842 INFO: Microblog Starting [in /Users/sadeliyi/Documents/Python Projects/microblog_app/app/__init__.py:44]
2020-07-15 03:26:50,488 INFO: Microblog Starting [in /Users/sadeliyi/Documents/Python Projects/microblog_app/app/__init__.py:44]
2020-07-15 03:28:15,331 ERROR: Exception on /follow/@feyi [POST] [in /Users/sadeliyi/Documents/Python Projects/microblog_app/venv/lib/python3.7/site-packages/flask/app.py:1892]
Traceback (most recent call last):
  File "/Users/sadeliyi/Documents/Python Projects/microblog_app/venv/lib/python3.7/site-packages/flask/app.py", line 2447, in wsgi_app
    response = self.full_dispatch_request()
  File "/Users/sadeliyi/Documents/Python Projects/microblog_app/venv/lib/python3.7/site-packages/flask/app.py", line 1952, in full_dispatch_request
    rv = self.handle_user_exception(e)
  File "/Users/sadeliyi/Documents/Python Projects/microblog_app/venv/lib/python3.7/site-packages/flask/app.py", line 1821, in handle_user_exception
    reraise(exc_type, exc_value, tb)
  File "/Users/sadeliyi/Documents/Python Projects/microblog_app/venv/lib/python3.7/site-packages/flask/_compat.py", line 39, in reraise
    raise value
  File "/Users/sadeliyi/Documents/Python Projects/microblog_app/venv/lib/python3.7/site-packages/flask/app.py", line 1950, in full_dispatch_request
    rv = self.dispatch_request()
  File "/Users/sadeliyi/Documents/Python Projects/microblog_app/venv/lib/python3.7/site-packages/flask/app.py", line 1936, in dispatch_request
    return self.view_functions[rule.endpoint](**req.view_args)
  File "/Users/sadeliyi/Documents/Python Projects/microblog_app/venv/lib/python3.7/site-packages/flask_login/utils.py", line 272, in decorated_view
    return func(*args, **kwargs)
  File "/Users/sadeliyi/Documents/Python Projects/microblog_app/app/routes.py", line 111, in follow
    current_user.follow(user)
  File "/Users/sadeliyi/Documents/Python Projects/microblog_app/app/models.py", line 38, in follow
    if not self.is_following(user):
  File "/Users/sadeliyi/Documents/Python Projects/microblog_app/app/models.py", line 46, in is_following
    return self.followed.filter(followers.c.follower_id == user.id).count() > 0
AttributeError: 'BaseQuery' object has no attribute 'id'
2020-07-15 03:31:41,823 INFO: Microblog Starting [in /Users/sadeliyi/Documents/Python Projects/microblog_app/app/__init__.py:44]
2020-07-15 03:32:05,368 ERROR: Exception on /follow/@feyi [POST] [in /Users/sadeliyi/Documents/Python Projects/microblog_app/venv/lib/python3.7/site-packages/flask/app.py:1892]
Traceback (most recent call last):
  File "/Users/sadeliyi/Documents/Python Projects/microblog_app/venv/lib/python3.7/site-packages/flask/app.py", line 2447, in wsgi_app
    response = self.full_dispatch_request()
  File "/Users/sadeliyi/Documents/Python Projects/microblog_app/venv/lib/python3.7/site-packages/flask/app.py", line 1952, in full_dispatch_request
    rv = self.handle_user_exception(e)
  File "/Users/sadeliyi/Documents/Python Projects/microblog_app/venv/lib/python3.7/site-packages/flask/app.py", line 1821, in handle_user_exception
    reraise(exc_type, exc_value, tb)
  File "/Users/sadeliyi/Documents/Python Projects/microblog_app/venv/lib/python3.7/site-packages/flask/_compat.py", line 39, in reraise
    raise value
  File "/Users/sadeliyi/Documents/Python Projects/microblog_app/venv/lib/python3.7/site-packages/flask/app.py", line 1950, in full_dispatch_request
    rv = self.dispatch_request()
  File "/Users/sadeliyi/Documents/Python Projects/microblog_app/venv/lib/python3.7/site-packages/flask/app.py", line 1936, in dispatch_request
    return self.view_functions[rule.endpoint](**req.view_args)
  File "/Users/sadeliyi/Documents/Python Projects/microblog_app/venv/lib/python3.7/site-packages/flask_login/utils.py", line 272, in decorated_view
    return func(*args, **kwargs)
  File "/Users/sadeliyi/Documents/Python Projects/microblog_app/app/routes.py", line 111, in follow
    current_user.follow(user)
  File "/Users/sadeliyi/Documents/Python Projects/microblog_app/app/models.py", line 38, in follow
    if not self.is_following(user):
  File "/Users/sadeliyi/Documents/Python Projects/microblog_app/app/models.py", line 46, in is_following
    return self.followed.filter(followers.c.followed_id == user.id).count() > 0
AttributeError: 'BaseQuery' object has no attribute 'id'
2020-07-15 03:41:26,791 INFO: Microblog Starting [in /Users/sadeliyi/Documents/Python Projects/microblog_app/app/__init__.py:44]
2020-07-15 03:41:54,728 ERROR: Exception on /user/@feyi [GET] [in /Users/sadeliyi/Documents/Python Projects/microblog_app/venv/lib/python3.7/site-packages/flask/app.py:1892]
Traceback (most recent call last):
  File "/Users/sadeliyi/Documents/Python Projects/microblog_app/venv/lib/python3.7/site-packages/flask/app.py", line 2447, in wsgi_app
    response = self.full_dispatch_request()
  File "/Users/sadeliyi/Documents/Python Projects/microblog_app/venv/lib/python3.7/site-packages/flask/app.py", line 1952, in full_dispatch_request
    rv = self.handle_user_exception(e)
  File "/Users/sadeliyi/Documents/Python Projects/microblog_app/venv/lib/python3.7/site-packages/flask/app.py", line 1821, in handle_user_exception
    reraise(exc_type, exc_value, tb)
  File "/Users/sadeliyi/Documents/Python Projects/microblog_app/venv/lib/python3.7/site-packages/flask/_compat.py", line 39, in reraise
    raise value
  File "/Users/sadeliyi/Documents/Python Projects/microblog_app/venv/lib/python3.7/site-packages/flask/app.py", line 1950, in full_dispatch_request
    rv = self.dispatch_request()
  File "/Users/sadeliyi/Documents/Python Projects/microblog_app/venv/lib/python3.7/site-packages/flask/app.py", line 1936, in dispatch_request
    return self.view_functions[rule.endpoint](**req.view_args)
  File "/Users/sadeliyi/Documents/Python Projects/microblog_app/venv/lib/python3.7/site-packages/flask_login/utils.py", line 272, in decorated_view
    return func(*args, **kwargs)
  File "/Users/sadeliyi/Documents/Python Projects/microblog_app/app/routes.py", line 80, in user
    return render_template('user.html', user=user, posts=posts, form=form)
  File "/Users/sadeliyi/Documents/Python Projects/microblog_app/venv/lib/python3.7/site-packages/flask/templating.py", line 140, in render_template
    ctx.app,
  File "/Users/sadeliyi/Documents/Python Projects/microblog_app/venv/lib/python3.7/site-packages/flask/templating.py", line 120, in _render
    rv = template.render(context)
  File "/Users/sadeliyi/Documents/Python Projects/microblog_app/venv/lib/python3.7/site-packages/jinja2/environment.py", line 1090, in render
    self.environment.handle_exception()
  File "/Users/sadeliyi/Documents/Python Projects/microblog_app/venv/lib/python3.7/site-packages/jinja2/environment.py", line 832, in handle_exception
    reraise(*rewrite_traceback_stack(source=source))
  File "/Users/sadeliyi/Documents/Python Projects/microblog_app/venv/lib/python3.7/site-packages/jinja2/_compat.py", line 28, in reraise
    raise value.with_traceback(tb)
  File "/Users/sadeliyi/Documents/Python Projects/microblog_app/app/templates/user.html", line 1, in top-level template code
    {% extends 'base.html' %}
  File "/Users/sadeliyi/Documents/Python Projects/microblog_app/app/templates/base.html", line 31, in top-level template code
    {% block content %}
  File "/Users/sadeliyi/Documents/Python Projects/microblog_app/app/templates/user.html", line 20, in block "content"
    {% elif not current_user.is_following(user) %}
  File "/Users/sadeliyi/Documents/Python Projects/microblog_app/app/models.py", line 46, in is_following
    return self.followed.filter(followers.c.followed_id == user.id).all().count() > 0
TypeError: count() takes exactly one argument (0 given)
2020-07-15 03:43:33,966 INFO: Microblog Starting [in /Users/sadeliyi/Documents/Python Projects/microblog_app/app/__init__.py:44]
2020-07-15 03:43:48,529 ERROR: Exception on /user/@ife [GET] [in /Users/sadeliyi/Documents/Python Projects/microblog_app/venv/lib/python3.7/site-packages/flask/app.py:1892]
Traceback (most recent call last):
  File "/Users/sadeliyi/Documents/Python Projects/microblog_app/venv/lib/python3.7/site-packages/flask/app.py", line 2447, in wsgi_app
    response = self.full_dispatch_request()
  File "/Users/sadeliyi/Documents/Python Projects/microblog_app/venv/lib/python3.7/site-packages/flask/app.py", line 1952, in full_dispatch_request
    rv = self.handle_user_exception(e)
  File "/Users/sadeliyi/Documents/Python Projects/microblog_app/venv/lib/python3.7/site-packages/flask/app.py", line 1821, in handle_user_exception
    reraise(exc_type, exc_value, tb)
  File "/Users/sadeliyi/Documents/Python Projects/microblog_app/venv/lib/python3.7/site-packages/flask/_compat.py", line 39, in reraise
    raise value
  File "/Users/sadeliyi/Documents/Python Projects/microblog_app/venv/lib/python3.7/site-packages/flask/app.py", line 1950, in full_dispatch_request
    rv = self.dispatch_request()
  File "/Users/sadeliyi/Documents/Python Projects/microblog_app/venv/lib/python3.7/site-packages/flask/app.py", line 1936, in dispatch_request
    return self.view_functions[rule.endpoint](**req.view_args)
  File "/Users/sadeliyi/Documents/Python Projects/microblog_app/venv/lib/python3.7/site-packages/flask_login/utils.py", line 272, in decorated_view
    return func(*args, **kwargs)
  File "/Users/sadeliyi/Documents/Python Projects/microblog_app/app/routes.py", line 80, in user
    return render_template('user.html', user=user, posts=posts, form=form)
  File "/Users/sadeliyi/Documents/Python Projects/microblog_app/venv/lib/python3.7/site-packages/flask/templating.py", line 140, in render_template
    ctx.app,
  File "/Users/sadeliyi/Documents/Python Projects/microblog_app/venv/lib/python3.7/site-packages/flask/templating.py", line 120, in _render
    rv = template.render(context)
  File "/Users/sadeliyi/Documents/Python Projects/microblog_app/venv/lib/python3.7/site-packages/jinja2/environment.py", line 1090, in render
    self.environment.handle_exception()
  File "/Users/sadeliyi/Documents/Python Projects/microblog_app/venv/lib/python3.7/site-packages/jinja2/environment.py", line 832, in handle_exception
    reraise(*rewrite_traceback_stack(source=source))
  File "/Users/sadeliyi/Documents/Python Projects/microblog_app/venv/lib/python3.7/site-packages/jinja2/_compat.py", line 28, in reraise
    raise value.with_traceback(tb)
  File "/Users/sadeliyi/Documents/Python Projects/microblog_app/app/templates/user.html", line 1, in top-level template code
    {% extends 'base.html' %}
  File "/Users/sadeliyi/Documents/Python Projects/microblog_app/app/templates/base.html", line 31, in top-level template code
    {% block content %}
  File "/Users/sadeliyi/Documents/Python Projects/microblog_app/app/templates/user.html", line 20, in block "content"
    {% elif not current_user.is_following(user) %}
  File "/Users/sadeliyi/Documents/Python Projects/microblog_app/app/models.py", line 46, in is_following
    return self.followed.filter(followers.c.followed_id == user.id).first().count() > 0
AttributeError: 'NoneType' object has no attribute 'count'
2020-07-15 03:47:08,176 INFO: Microblog Starting [in /Users/sadeliyi/Documents/Python Projects/microblog_app/app/__init__.py:44]
2020-07-15 03:47:35,899 ERROR: Exception on /follow/@feyi [POST] [in /Users/sadeliyi/Documents/Python Projects/microblog_app/venv/lib/python3.7/site-packages/flask/app.py:1892]
Traceback (most recent call last):
  File "/Users/sadeliyi/Documents/Python Projects/microblog_app/venv/lib/python3.7/site-packages/flask/app.py", line 2447, in wsgi_app
    response = self.full_dispatch_request()
  File "/Users/sadeliyi/Documents/Python Projects/microblog_app/venv/lib/python3.7/site-packages/flask/app.py", line 1952, in full_dispatch_request
    rv = self.handle_user_exception(e)
  File "/Users/sadeliyi/Documents/Python Projects/microblog_app/venv/lib/python3.7/site-packages/flask/app.py", line 1821, in handle_user_exception
    reraise(exc_type, exc_value, tb)
  File "/Users/sadeliyi/Documents/Python Projects/microblog_app/venv/lib/python3.7/site-packages/flask/_compat.py", line 39, in reraise
    raise value
  File "/Users/sadeliyi/Documents/Python Projects/microblog_app/venv/lib/python3.7/site-packages/flask/app.py", line 1950, in full_dispatch_request
    rv = self.dispatch_request()
  File "/Users/sadeliyi/Documents/Python Projects/microblog_app/venv/lib/python3.7/site-packages/flask/app.py", line 1936, in dispatch_request
    return self.view_functions[rule.endpoint](**req.view_args)
  File "/Users/sadeliyi/Documents/Python Projects/microblog_app/venv/lib/python3.7/site-packages/flask_login/utils.py", line 272, in decorated_view
    return func(*args, **kwargs)
  File "/Users/sadeliyi/Documents/Python Projects/microblog_app/app/routes.py", line 111, in follow
    current_user.follow(user)
  File "/Users/sadeliyi/Documents/Python Projects/microblog_app/app/models.py", line 38, in follow
    if not self.is_following(user):
  File "/Users/sadeliyi/Documents/Python Projects/microblog_app/app/models.py", line 46, in is_following
    return self.followed.filter(followers.c.followed_id == user.id).first() is not None
AttributeError: 'BaseQuery' object has no attribute 'id'
2020-07-15 03:49:10,890 INFO: Microblog Starting [in /Users/sadeliyi/Documents/Python Projects/microblog_app/app/__init__.py:44]
2020-07-15 03:49:53,388 ERROR: Exception on /unfollow/@feyi [POST] [in /Users/sadeliyi/Documents/Python Projects/microblog_app/venv/lib/python3.7/site-packages/flask/app.py:1892]
Traceback (most recent call last):
  File "/Users/sadeliyi/Documents/Python Projects/microblog_app/venv/lib/python3.7/site-packages/flask/app.py", line 2447, in wsgi_app
    response = self.full_dispatch_request()
  File "/Users/sadeliyi/Documents/Python Projects/microblog_app/venv/lib/python3.7/site-packages/flask/app.py", line 1952, in full_dispatch_request
    rv = self.handle_user_exception(e)
  File "/Users/sadeliyi/Documents/Python Projects/microblog_app/venv/lib/python3.7/site-packages/flask/app.py", line 1821, in handle_user_exception
    reraise(exc_type, exc_value, tb)
  File "/Users/sadeliyi/Documents/Python Projects/microblog_app/venv/lib/python3.7/site-packages/flask/_compat.py", line 39, in reraise
    raise value
  File "/Users/sadeliyi/Documents/Python Projects/microblog_app/venv/lib/python3.7/site-packages/flask/app.py", line 1950, in full_dispatch_request
    rv = self.dispatch_request()
  File "/Users/sadeliyi/Documents/Python Projects/microblog_app/venv/lib/python3.7/site-packages/flask/app.py", line 1936, in dispatch_request
    return self.view_functions[rule.endpoint](**req.view_args)
  File "/Users/sadeliyi/Documents/Python Projects/microblog_app/venv/lib/python3.7/site-packages/flask_login/utils.py", line 272, in decorated_view
    return func(*args, **kwargs)
  File "/Users/sadeliyi/Documents/Python Projects/microblog_app/app/routes.py", line 131, in unfollow
    current_user.unfollow(user)
  File "/Users/sadeliyi/Documents/Python Projects/microblog_app/app/models.py", line 42, in unfollow
    if self.is_following(user):
  File "/Users/sadeliyi/Documents/Python Projects/microblog_app/app/models.py", line 46, in is_following
    return self.followed.filter(followers.c.followed_id == user.id).all() is not None
AttributeError: 'BaseQuery' object has no attribute 'id'
2020-07-15 19:50:48,410 INFO: Microblog Starting [in /Users/sadeliyi/Documents/Python Projects/microblog_app/app/__init__.py:44]
2020-07-15 20:02:56,453 INFO: Microblog Starting [in /Users/sadeliyi/Documents/Python Projects/microblog_app/app/__init__.py:44]
2020-07-15 20:13:31,397 INFO: Microblog Starting [in /Users/sadeliyi/Documents/Python Projects/microblog_app/app/__init__.py:44]
2020-07-15 20:19:37,611 INFO: Microblog Starting [in /Users/sadeliyi/Documents/Python Projects/microblog_app/app/__init__.py:44]
2020-07-15 20:22:39,778 INFO: Microblog Starting [in /Users/sadeliyi/Documents/Python Projects/microblog_app/app/__init__.py:44]
2020-07-15 20:24:27,695 INFO: Microblog Starting [in /Users/sadeliyi/Documents/Python Projects/microblog_app/app/__init__.py:44]
2020-07-15 20:26:20,409 INFO: Microblog Starting [in /Users/sadeliyi/Documents/Python Projects/microblog_app/app/__init__.py:44]
2020-07-15 20:29:04,515 INFO: Microblog Starting [in /Users/sadeliyi/Documents/Python Projects/microblog_app/app/__init__.py:44]
2020-07-15 20:42:16,554 INFO: Microblog Starting [in /Users/sadeliyi/Documents/Python Projects/microblog_app/app/__init__.py:44]
2020-07-15 20:44:09,775 INFO: Microblog Starting [in /Users/sadeliyi/Documents/Python Projects/microblog_app/app/__init__.py:44]
2020-07-15 20:45:44,891 ERROR: Exception on /follow/@feyi [POST] [in /Users/sadeliyi/Documents/Python Projects/microblog_app/venv/lib/python3.7/site-packages/flask/app.py:1892]
Traceback (most recent call last):
  File "/Users/sadeliyi/Documents/Python Projects/microblog_app/venv/lib/python3.7/site-packages/flask/app.py", line 2447, in wsgi_app
    response = self.full_dispatch_request()
  File "/Users/sadeliyi/Documents/Python Projects/microblog_app/venv/lib/python3.7/site-packages/flask/app.py", line 1952, in full_dispatch_request
    rv = self.handle_user_exception(e)
  File "/Users/sadeliyi/Documents/Python Projects/microblog_app/venv/lib/python3.7/site-packages/flask/app.py", line 1821, in handle_user_exception
    reraise(exc_type, exc_value, tb)
  File "/Users/sadeliyi/Documents/Python Projects/microblog_app/venv/lib/python3.7/site-packages/flask/_compat.py", line 39, in reraise
    raise value
  File "/Users/sadeliyi/Documents/Python Projects/microblog_app/venv/lib/python3.7/site-packages/flask/app.py", line 1950, in full_dispatch_request
    rv = self.dispatch_request()
  File "/Users/sadeliyi/Documents/Python Projects/microblog_app/venv/lib/python3.7/site-packages/flask/app.py", line 1936, in dispatch_request
    return self.view_functions[rule.endpoint](**req.view_args)
  File "/Users/sadeliyi/Documents/Python Projects/microblog_app/venv/lib/python3.7/site-packages/flask_login/utils.py", line 272, in decorated_view
    return func(*args, **kwargs)
  File "/Users/sadeliyi/Documents/Python Projects/microblog_app/app/routes.py", line 111, in follow
    current_user.follow(user)
  File "/Users/sadeliyi/Documents/Python Projects/microblog_app/app/models.py", line 38, in follow
    if not self.is_following(user):
  File "/Users/sadeliyi/Documents/Python Projects/microblog_app/app/models.py", line 46, in is_following
    return self.followed.filter(followers.c.followed_id == user.id).count() > 0
AttributeError: 'BaseQuery' object has no attribute 'id'
2020-07-15 21:57:58,400 INFO: Microblog Starting [in /Users/sadeliyi/Documents/Python Projects/microblog_app/app/__init__.py:44]
2020-07-16 11:10:16,100 INFO: Microblog Starting [in /Users/sadeliyi/Documents/Python Projects/microblog_app/app/__init__.py:44]
2020-07-16 11:28:34,032 INFO: Microblog Starting [in /Users/sadeliyi/Documents/Python Projects/microblog_app/app/__init__.py:44]
2020-07-16 11:28:43,727 INFO: Microblog Starting [in /Users/sadeliyi/Documents/Python Projects/microblog_app/app/__init__.py:44]
2020-07-16 11:30:32,037 ERROR: Exception on /follow/@feyi [POST] [in /Users/sadeliyi/Documents/Python Projects/microblog_app/venv/lib/python3.7/site-packages/flask/app.py:1892]
Traceback (most recent call last):
  File "/Users/sadeliyi/Documents/Python Projects/microblog_app/venv/lib/python3.7/site-packages/flask/app.py", line 2447, in wsgi_app
    response = self.full_dispatch_request()
  File "/Users/sadeliyi/Documents/Python Projects/microblog_app/venv/lib/python3.7/site-packages/flask/app.py", line 1952, in full_dispatch_request
    rv = self.handle_user_exception(e)
  File "/Users/sadeliyi/Documents/Python Projects/microblog_app/venv/lib/python3.7/site-packages/flask/app.py", line 1821, in handle_user_exception
    reraise(exc_type, exc_value, tb)
  File "/Users/sadeliyi/Documents/Python Projects/microblog_app/venv/lib/python3.7/site-packages/flask/_compat.py", line 39, in reraise
    raise value
  File "/Users/sadeliyi/Documents/Python Projects/microblog_app/venv/lib/python3.7/site-packages/flask/app.py", line 1950, in full_dispatch_request
    rv = self.dispatch_request()
  File "/Users/sadeliyi/Documents/Python Projects/microblog_app/venv/lib/python3.7/site-packages/flask/app.py", line 1936, in dispatch_request
    return self.view_functions[rule.endpoint](**req.view_args)
  File "/Users/sadeliyi/Documents/Python Projects/microblog_app/venv/lib/python3.7/site-packages/flask_login/utils.py", line 272, in decorated_view
    return func(*args, **kwargs)
  File "/Users/sadeliyi/Documents/Python Projects/microblog_app/app/routes.py", line 111, in follow
    current_user.follow(user)
  File "/Users/sadeliyi/Documents/Python Projects/microblog_app/app/models.py", line 38, in follow
    if not self.is_following(user):
  File "/Users/sadeliyi/Documents/Python Projects/microblog_app/app/models.py", line 46, in is_following
    return self.followed.filter(followers.c.followed_id == user.id).count() > 0
AttributeError: 'BaseQuery' object has no attribute 'id'
2020-07-16 13:47:35,420 INFO: Microblog Starting [in /Users/sadeliyi/Documents/Python Projects/microblog_app/app/__init__.py:44]
2020-07-16 13:47:56,166 INFO: Microblog Starting [in /Users/sadeliyi/Documents/Python Projects/microblog_app/app/__init__.py:44]
2020-07-16 13:48:45,384 ERROR: Exception on /follow/@ife [POST] [in /Users/sadeliyi/Documents/Python Projects/microblog_app/venv/lib/python3.7/site-packages/flask/app.py:1892]
Traceback (most recent call last):
  File "/Users/sadeliyi/Documents/Python Projects/microblog_app/venv/lib/python3.7/site-packages/flask/app.py", line 2447, in wsgi_app
    response = self.full_dispatch_request()
  File "/Users/sadeliyi/Documents/Python Projects/microblog_app/venv/lib/python3.7/site-packages/flask/app.py", line 1952, in full_dispatch_request
    rv = self.handle_user_exception(e)
  File "/Users/sadeliyi/Documents/Python Projects/microblog_app/venv/lib/python3.7/site-packages/flask/app.py", line 1821, in handle_user_exception
    reraise(exc_type, exc_value, tb)
  File "/Users/sadeliyi/Documents/Python Projects/microblog_app/venv/lib/python3.7/site-packages/flask/_compat.py", line 39, in reraise
    raise value
  File "/Users/sadeliyi/Documents/Python Projects/microblog_app/venv/lib/python3.7/site-packages/flask/app.py", line 1950, in full_dispatch_request
    rv = self.dispatch_request()
  File "/Users/sadeliyi/Documents/Python Projects/microblog_app/venv/lib/python3.7/site-packages/flask/app.py", line 1936, in dispatch_request
    return self.view_functions[rule.endpoint](**req.view_args)
  File "/Users/sadeliyi/Documents/Python Projects/microblog_app/venv/lib/python3.7/site-packages/flask_login/utils.py", line 272, in decorated_view
    return func(*args, **kwargs)
  File "/Users/sadeliyi/Documents/Python Projects/microblog_app/app/routes.py", line 111, in follow
    current_user.follow(user)
  File "/Users/sadeliyi/Documents/Python Projects/microblog_app/app/models.py", line 38, in follow
    if not self.is_following(user):
  File "/Users/sadeliyi/Documents/Python Projects/microblog_app/app/models.py", line 47, in is_following
    return len(list(self.followed.filter(followers.c.followed_id == user.id))) > 0
AttributeError: 'BaseQuery' object has no attribute 'id'
2020-07-16 13:49:15,268 ERROR: Exception on /follow/@ife [POST] [in /Users/sadeliyi/Documents/Python Projects/microblog_app/venv/lib/python3.7/site-packages/flask/app.py:1892]
Traceback (most recent call last):
  File "/Users/sadeliyi/Documents/Python Projects/microblog_app/venv/lib/python3.7/site-packages/flask/app.py", line 2447, in wsgi_app
    response = self.full_dispatch_request()
  File "/Users/sadeliyi/Documents/Python Projects/microblog_app/venv/lib/python3.7/site-packages/flask/app.py", line 1952, in full_dispatch_request
    rv = self.handle_user_exception(e)
  File "/Users/sadeliyi/Documents/Python Projects/microblog_app/venv/lib/python3.7/site-packages/flask/app.py", line 1821, in handle_user_exception
    reraise(exc_type, exc_value, tb)
  File "/Users/sadeliyi/Documents/Python Projects/microblog_app/venv/lib/python3.7/site-packages/flask/_compat.py", line 39, in reraise
    raise value
  File "/Users/sadeliyi/Documents/Python Projects/microblog_app/venv/lib/python3.7/site-packages/flask/app.py", line 1950, in full_dispatch_request
    rv = self.dispatch_request()
  File "/Users/sadeliyi/Documents/Python Projects/microblog_app/venv/lib/python3.7/site-packages/flask/app.py", line 1936, in dispatch_request
    return self.view_functions[rule.endpoint](**req.view_args)
  File "/Users/sadeliyi/Documents/Python Projects/microblog_app/venv/lib/python3.7/site-packages/flask_login/utils.py", line 272, in decorated_view
    return func(*args, **kwargs)
  File "/Users/sadeliyi/Documents/Python Projects/microblog_app/app/routes.py", line 111, in follow
    current_user.follow(user)
  File "/Users/sadeliyi/Documents/Python Projects/microblog_app/app/models.py", line 38, in follow
    if not self.is_following(user):
  File "/Users/sadeliyi/Documents/Python Projects/microblog_app/app/models.py", line 47, in is_following
    return len(list(self.followed.filter(followers.c.followed_id == user.id))) > 0
AttributeError: 'BaseQuery' object has no attribute 'id'
2020-07-19 21:59:43,181 INFO: Microblog Starting [in /Users/sadeliyi/Documents/Python Projects/microblog_app/app/__init__.py:44]
2020-07-20 02:19:11,678 INFO: Microblog Starting [in /Users/sadeliyi/Documents/Python Projects/microblog_app/app/__init__.py:44]
2020-07-20 02:19:26,734 ERROR: Exception on / [GET] [in /Users/sadeliyi/Documents/Python Projects/microblog_app/venv/lib/python3.7/site-packages/flask/app.py:1892]
Traceback (most recent call last):
  File "/Users/sadeliyi/Documents/Python Projects/microblog_app/venv/lib/python3.7/site-packages/flask/app.py", line 2447, in wsgi_app
    response = self.full_dispatch_request()
  File "/Users/sadeliyi/Documents/Python Projects/microblog_app/venv/lib/python3.7/site-packages/flask/app.py", line 1952, in full_dispatch_request
    rv = self.handle_user_exception(e)
  File "/Users/sadeliyi/Documents/Python Projects/microblog_app/venv/lib/python3.7/site-packages/flask/app.py", line 1821, in handle_user_exception
    reraise(exc_type, exc_value, tb)
  File "/Users/sadeliyi/Documents/Python Projects/microblog_app/venv/lib/python3.7/site-packages/flask/_compat.py", line 39, in reraise
    raise value
  File "/Users/sadeliyi/Documents/Python Projects/microblog_app/venv/lib/python3.7/site-packages/flask/app.py", line 1950, in full_dispatch_request
    rv = self.dispatch_request()
  File "/Users/sadeliyi/Documents/Python Projects/microblog_app/venv/lib/python3.7/site-packages/flask/app.py", line 1936, in dispatch_request
    return self.view_functions[rule.endpoint](**req.view_args)
  File "/Users/sadeliyi/Documents/Python Projects/microblog_app/venv/lib/python3.7/site-packages/flask_login/utils.py", line 272, in decorated_view
    return func(*args, **kwargs)
  File "/Users/sadeliyi/Documents/Python Projects/microblog_app/app/routes.py", line 32, in index
    return render_template('index.html', title='Home', posts=posts)
  File "/Users/sadeliyi/Documents/Python Projects/microblog_app/venv/lib/python3.7/site-packages/flask/templating.py", line 140, in render_template
    ctx.app,
  File "/Users/sadeliyi/Documents/Python Projects/microblog_app/venv/lib/python3.7/site-packages/flask/templating.py", line 120, in _render
    rv = template.render(context)
  File "/Users/sadeliyi/Documents/Python Projects/microblog_app/venv/lib/python3.7/site-packages/jinja2/environment.py", line 1090, in render
    self.environment.handle_exception()
  File "/Users/sadeliyi/Documents/Python Projects/microblog_app/venv/lib/python3.7/site-packages/jinja2/environment.py", line 832, in handle_exception
    reraise(*rewrite_traceback_stack(source=source))
  File "/Users/sadeliyi/Documents/Python Projects/microblog_app/venv/lib/python3.7/site-packages/jinja2/_compat.py", line 28, in reraise
    raise value.with_traceback(tb)
  File "/Users/sadeliyi/Documents/Python Projects/microblog_app/app/templates/index.html", line 1, in top-level template code
    {% extends 'base.html' %}
  File "/Users/sadeliyi/Documents/Python Projects/microblog_app/app/templates/base.html", line 31, in top-level template code
    {% block content %}
  File "/Users/sadeliyi/Documents/Python Projects/microblog_app/app/templates/index.html", line 6, in block "content"
    {{ form.hidden_tag() }}
  File "/Users/sadeliyi/Documents/Python Projects/microblog_app/venv/lib/python3.7/site-packages/jinja2/environment.py", line 471, in getattr
    return getattr(obj, attribute)
jinja2.exceptions.UndefinedError: 'form' is undefined
2020-07-20 02:19:57,012 INFO: Microblog Starting [in /Users/sadeliyi/Documents/Python Projects/microblog_app/app/__init__.py:44]
2020-07-20 02:20:50,775 INFO: Microblog Starting [in /Users/sadeliyi/Documents/Python Projects/microblog_app/app/__init__.py:44]
2020-07-20 02:22:45,426 INFO: Microblog Starting [in /Users/sadeliyi/Documents/Python Projects/microblog_app/app/__init__.py:44]
2020-07-20 08:25:05,368 INFO: Microblog Starting [in /Users/sadeliyi/Documents/Python Projects/microblog_app/app/__init__.py:44]
2020-07-27 02:10:29,200 INFO: Microblog Starting [in /Users/sadeliyi/Documents/Python Projects/microblog_app/app/__init__.py:44]
2020-07-27 02:50:30,167 INFO: Microblog Starting [in /Users/sadeliyi/Documents/Python Projects/microblog_app/app/__init__.py:44]
2020-07-27 02:52:50,901 INFO: Microblog Starting [in /Users/sadeliyi/Documents/Python Projects/microblog_app/app/__init__.py:44]
2020-07-27 03:05:30,756 INFO: Microblog Starting [in /Users/sadeliyi/Documents/Python Projects/microblog_app/app/__init__.py:44]
2020-07-28 01:46:51,936 INFO: Microblog Starting [in /Users/sadeliyi/Documents/Python Projects/microblog_app/app/__init__.py:44]
2020-07-28 01:47:00,354 ERROR: Exception on /index [GET] [in /Users/sadeliyi/Documents/Python Projects/microblog_app/venv/lib/python3.7/site-packages/flask/app.py:1892]
Traceback (most recent call last):
  File "/Users/sadeliyi/Documents/Python Projects/microblog_app/venv/lib/python3.7/site-packages/flask/app.py", line 2447, in wsgi_app
    response = self.full_dispatch_request()
  File "/Users/sadeliyi/Documents/Python Projects/microblog_app/venv/lib/python3.7/site-packages/flask/app.py", line 1952, in full_dispatch_request
    rv = self.handle_user_exception(e)
  File "/Users/sadeliyi/Documents/Python Projects/microblog_app/venv/lib/python3.7/site-packages/flask/app.py", line 1821, in handle_user_exception
    reraise(exc_type, exc_value, tb)
  File "/Users/sadeliyi/Documents/Python Projects/microblog_app/venv/lib/python3.7/site-packages/flask/_compat.py", line 39, in reraise
    raise value
  File "/Users/sadeliyi/Documents/Python Projects/microblog_app/venv/lib/python3.7/site-packages/flask/app.py", line 1950, in full_dispatch_request
    rv = self.dispatch_request()
  File "/Users/sadeliyi/Documents/Python Projects/microblog_app/venv/lib/python3.7/site-packages/flask/app.py", line 1936, in dispatch_request
    return self.view_functions[rule.endpoint](**req.view_args)
  File "/Users/sadeliyi/Documents/Python Projects/microblog_app/venv/lib/python3.7/site-packages/flask_login/utils.py", line 272, in decorated_view
    return func(*args, **kwargs)
  File "/Users/sadeliyi/Documents/Python Projects/microblog_app/app/routes.py", line 31, in index
    posts = current_user.followed_posts.paginate(page, app.config['RESULTS_PER_PAGE'], False)
AttributeError: 'function' object has no attribute 'paginate'
2020-07-28 01:50:04,083 INFO: Microblog Starting [in /Users/sadeliyi/Documents/Python Projects/microblog_app/app/__init__.py:44]
2020-07-28 02:18:51,306 INFO: Microblog Starting [in /Users/sadeliyi/Documents/Python Projects/microblog_app/app/__init__.py:44]
2020-07-28 02:18:55,438 ERROR: Exception on /index [GET] [in /Users/sadeliyi/Documents/Python Projects/microblog_app/venv/lib/python3.7/site-packages/flask/app.py:1892]
Traceback (most recent call last):
  File "/Users/sadeliyi/Documents/Python Projects/microblog_app/venv/lib/python3.7/site-packages/flask/app.py", line 2447, in wsgi_app
    response = self.full_dispatch_request()
  File "/Users/sadeliyi/Documents/Python Projects/microblog_app/venv/lib/python3.7/site-packages/flask/app.py", line 1952, in full_dispatch_request
    rv = self.handle_user_exception(e)
  File "/Users/sadeliyi/Documents/Python Projects/microblog_app/venv/lib/python3.7/site-packages/flask/app.py", line 1821, in handle_user_exception
    reraise(exc_type, exc_value, tb)
  File "/Users/sadeliyi/Documents/Python Projects/microblog_app/venv/lib/python3.7/site-packages/flask/_compat.py", line 39, in reraise
    raise value
  File "/Users/sadeliyi/Documents/Python Projects/microblog_app/venv/lib/python3.7/site-packages/flask/app.py", line 1950, in full_dispatch_request
    rv = self.dispatch_request()
  File "/Users/sadeliyi/Documents/Python Projects/microblog_app/venv/lib/python3.7/site-packages/flask/app.py", line 1936, in dispatch_request
    return self.view_functions[rule.endpoint](**req.view_args)
  File "/Users/sadeliyi/Documents/Python Projects/microblog_app/venv/lib/python3.7/site-packages/flask_login/utils.py", line 272, in decorated_view
    return func(*args, **kwargs)
  File "/Users/sadeliyi/Documents/Python Projects/microblog_app/app/routes.py", line 36, in index
    next_url=next_url, form=form)
  File "/Users/sadeliyi/Documents/Python Projects/microblog_app/venv/lib/python3.7/site-packages/flask/templating.py", line 138, in render_template
    ctx.app.jinja_env.get_or_select_template(template_name_or_list),
  File "/Users/sadeliyi/Documents/Python Projects/microblog_app/venv/lib/python3.7/site-packages/jinja2/environment.py", line 930, in get_or_select_template
    return self.get_template(template_name_or_list, parent, globals)
  File "/Users/sadeliyi/Documents/Python Projects/microblog_app/venv/lib/python3.7/site-packages/jinja2/environment.py", line 883, in get_template
    return self._load_template(name, self.make_globals(globals))
  File "/Users/sadeliyi/Documents/Python Projects/microblog_app/venv/lib/python3.7/site-packages/jinja2/environment.py", line 857, in _load_template
    template = self.loader.load(self, name, globals)
  File "/Users/sadeliyi/Documents/Python Projects/microblog_app/venv/lib/python3.7/site-packages/jinja2/loaders.py", line 127, in load
    code = environment.compile(source, name, filename)
  File "/Users/sadeliyi/Documents/Python Projects/microblog_app/venv/lib/python3.7/site-packages/jinja2/environment.py", line 638, in compile
    self.handle_exception(source=source_hint)
  File "/Users/sadeliyi/Documents/Python Projects/microblog_app/venv/lib/python3.7/site-packages/jinja2/environment.py", line 832, in handle_exception
    reraise(*rewrite_traceback_stack(source=source))
  File "/Users/sadeliyi/Documents/Python Projects/microblog_app/venv/lib/python3.7/site-packages/jinja2/_compat.py", line 28, in reraise
    raise value.with_traceback(tb)
  File "/Users/sadeliyi/Documents/Python Projects/microblog_app/app/templates/index.html", line 25, in template
    {% endblock %}
jinja2.exceptions.TemplateSyntaxError: Encountered unknown tag 'endblock'. You probably made a nesting mistake. Jinja is expecting this tag, but currently looking for 'elif' or 'else' or 'endif'. The innermost block that needs to be closed is 'if'.
2020-07-28 02:19:24,929 INFO: Microblog Starting [in /Users/sadeliyi/Documents/Python Projects/microblog_app/app/__init__.py:44]
2020-07-28 02:25:58,302 INFO: Microblog Starting [in /Users/sadeliyi/Documents/Python Projects/microblog_app/app/__init__.py:44]
2020-07-28 02:26:22,710 INFO: Microblog Starting [in /Users/sadeliyi/Documents/Python Projects/microblog_app/app/__init__.py:44]
2020-07-28 02:26:53,501 INFO: Microblog Starting [in /Users/sadeliyi/Documents/Python Projects/microblog_app/app/__init__.py:44]
2020-07-28 02:39:10,520 INFO: Microblog Starting [in /Users/sadeliyi/Documents/Python Projects/microblog_app/app/__init__.py:44]
