2020-07-28 02:39:35,333 ERROR: Exception on /user/@ife [GET] [in /Users/sadeliyi/Documents/Python Projects/microblog_app/venv/lib/python3.7/site-packages/flask/app.py:1892]
Traceback (most recent call last):
  File "/Users/sadeliyi/Documents/Python Projects/microblog_app/venv/lib/python3.7/site-packages/sqlalchemy/orm/attributes.py", line 229, in __getattr__
    return getattr(self.comparator, key)
AttributeError: 'Comparator' object has no attribute 'order_by'

The above exception was the direct cause of the following exception:

Traceback (most recent call last):
  File "/Users/sadeliyi/Documents/Python Projects/microblog_app/venv/lib/python3.7/site-packages/flask/app.py", line 2447, in wsgi_app
    response = self.full_dispatch_request()
  File "/Users/sadeliyi/Documents/Python Projects/microblog_app/venv/lib/python3.7/site-packages/flask/app.py", line 1952, in full_dispatch_request
    rv = self.handle_user_exception(e)
  File "/Users/sadeliyi/Documents/Python Projects/microblog_app/venv/lib/python3.7/site-packages/flask/app.py", line 1821, in handle_user_exception
    reraise(exc_type, exc_value, tb)
  File "/Users/sadeliyi/Documents/Python Projects/microblog_app/venv/lib/python3.7/site-packages/flask/_compat.py", line 39, in reraise
    raise value
  File "/Users/sadeliyi/Documents/Python Projects/microblog_app/venv/lib/python3.7/site-packages/flask/app.py", line 1950, in full_dispatch_request
    rv = self.dispatch_request()
  File "/Users/sadeliyi/Documents/Python Projects/microblog_app/venv/lib/python3.7/site-packages/flask/app.py", line 1936, in dispatch_request
    return self.view_functions[rule.endpoint](**req.view_args)
  File "/Users/sadeliyi/Documents/Python Projects/microblog_app/venv/lib/python3.7/site-packages/flask_login/utils.py", line 272, in decorated_view
    return func(*args, **kwargs)
  File "/Users/sadeliyi/Documents/Python Projects/microblog_app/app/routes.py", line 91, in user
    posts = User.posts.order_by(Post.timestamp.desc()).paginate(page, app.config['RESULTS_PER_PAGE'], False)
  File "/Users/sadeliyi/Documents/Python Projects/microblog_app/venv/lib/python3.7/site-packages/sqlalchemy/orm/attributes.py", line 242, in __getattr__
    replace_context=err,
  File "/Users/sadeliyi/Documents/Python Projects/microblog_app/venv/lib/python3.7/site-packages/sqlalchemy/util/compat.py", line 178, in raise_
    raise exception
AttributeError: Neither 'InstrumentedAttribute' object nor 'Comparator' object associated with User.posts has an attribute 'order_by'
2020-07-28 02:41:10,441 INFO: Microblog Starting [in /Users/sadeliyi/Documents/Python Projects/microblog_app/app/__init__.py:44]
2020-08-01 16:50:05,034 INFO: Microblog Starting [in /Users/sadeliyi/Documents/Python Projects/microblog_app/app/__init__.py:46]
2020-08-02 11:56:03,700 INFO: Microblog Starting [in /Users/sadeliyi/Documents/Python Projects/microblog_app/app/__init__.py:46]
2020-08-02 12:05:20,489 INFO: Microblog Starting [in /Users/sadeliyi/Documents/Python Projects/microblog_app/app/__init__.py:46]
2020-08-02 16:31:11,378 INFO: Microblog Starting [in /Users/sadeliyi/Documents/Python Projects/microblog_app/app/__init__.py:46]
2020-08-02 16:31:30,310 ERROR: Exception on /login [GET] [in /Users/sadeliyi/Documents/Python Projects/microblog_app/venv/lib/python3.7/site-packages/flask/app.py:1892]
Traceback (most recent call last):
  File "/Users/sadeliyi/Documents/Python Projects/microblog_app/venv/lib/python3.7/site-packages/flask/app.py", line 2447, in wsgi_app
    response = self.full_dispatch_request()
  File "/Users/sadeliyi/Documents/Python Projects/microblog_app/venv/lib/python3.7/site-packages/flask/app.py", line 1952, in full_dispatch_request
    rv = self.handle_user_exception(e)
  File "/Users/sadeliyi/Documents/Python Projects/microblog_app/venv/lib/python3.7/site-packages/flask/app.py", line 1821, in handle_user_exception
    reraise(exc_type, exc_value, tb)
  File "/Users/sadeliyi/Documents/Python Projects/microblog_app/venv/lib/python3.7/site-packages/flask/_compat.py", line 39, in reraise
    raise value
  File "/Users/sadeliyi/Documents/Python Projects/microblog_app/venv/lib/python3.7/site-packages/flask/app.py", line 1950, in full_dispatch_request
    rv = self.dispatch_request()
  File "/Users/sadeliyi/Documents/Python Projects/microblog_app/venv/lib/python3.7/site-packages/flask/app.py", line 1936, in dispatch_request
    return self.view_functions[rule.endpoint](**req.view_args)
  File "/Users/sadeliyi/Documents/Python Projects/microblog_app/app/routes.py", line 62, in login
    return render_template('login.html', title='Sign In', form=form)
  File "/Users/sadeliyi/Documents/Python Projects/microblog_app/venv/lib/python3.7/site-packages/flask/templating.py", line 140, in render_template
    ctx.app,
  File "/Users/sadeliyi/Documents/Python Projects/microblog_app/venv/lib/python3.7/site-packages/flask/templating.py", line 120, in _render
    rv = template.render(context)
  File "/Users/sadeliyi/Documents/Python Projects/microblog_app/venv/lib/python3.7/site-packages/jinja2/environment.py", line 1090, in render
    self.environment.handle_exception()
  File "/Users/sadeliyi/Documents/Python Projects/microblog_app/venv/lib/python3.7/site-packages/jinja2/environment.py", line 832, in handle_exception
    reraise(*rewrite_traceback_stack(source=source))
  File "/Users/sadeliyi/Documents/Python Projects/microblog_app/venv/lib/python3.7/site-packages/jinja2/_compat.py", line 28, in reraise
    raise value.with_traceback(tb)
  File "/Users/sadeliyi/Documents/Python Projects/microblog_app/app/templates/login.html", line 1, in top-level template code
    {% extends 'base.html' %}
  File "/Users/sadeliyi/Documents/Python Projects/microblog_app/app/templates/base.html", line 32, in top-level template code
    {% block content %}
  File "/Users/sadeliyi/Documents/Python Projects/microblog_app/app/templates/login.html", line 25, in block "content"
    &nbsp;&nbsp; Forgot Password? <a href="{{ url_for('reset_password') }}"> Click here to Reset </a>
  File "/Users/sadeliyi/Documents/Python Projects/microblog_app/venv/lib/python3.7/site-packages/flask/helpers.py", line 370, in url_for
    return appctx.app.handle_url_build_error(error, endpoint, values)
  File "/Users/sadeliyi/Documents/Python Projects/microblog_app/venv/lib/python3.7/site-packages/flask/app.py", line 2216, in handle_url_build_error
    reraise(exc_type, exc_value, tb)
  File "/Users/sadeliyi/Documents/Python Projects/microblog_app/venv/lib/python3.7/site-packages/flask/_compat.py", line 39, in reraise
    raise value
  File "/Users/sadeliyi/Documents/Python Projects/microblog_app/venv/lib/python3.7/site-packages/flask/helpers.py", line 358, in url_for
    endpoint, values, method=method, force_external=external
  File "/Users/sadeliyi/Documents/Python Projects/microblog_app/venv/lib/python3.7/site-packages/werkzeug/routing.py", line 2179, in build
    raise BuildError(endpoint, values, method, self)
werkzeug.routing.BuildError: Could not build url for endpoint 'reset_password'. Did you forget to specify values ['token']?
2020-08-02 16:32:48,991 INFO: Microblog Starting [in /Users/sadeliyi/Documents/Python Projects/microblog_app/app/__init__.py:46]
2020-08-02 17:11:19,321 INFO: Microblog Starting [in /Users/sadeliyi/Documents/Python Projects/microblog_app/app/__init__.py:47]
2020-08-02 17:12:23,385 INFO: Microblog Starting [in /Users/sadeliyi/Documents/Python Projects/microblog_app/app/__init__.py:47]
2020-08-02 17:15:52,310 INFO: Microblog Starting [in /Users/sadeliyi/Documents/Python Projects/microblog_app/app/__init__.py:48]
2020-08-02 17:16:35,070 INFO: Microblog Starting [in /Users/sadeliyi/Documents/Python Projects/microblog_app/app/__init__.py:48]
2020-08-02 17:19:16,695 INFO: Microblog Starting [in /Users/sadeliyi/Documents/Python Projects/microblog_app/app/__init__.py:48]
2020-08-02 17:21:09,672 INFO: Microblog Starting [in /Users/sadeliyi/Documents/Python Projects/microblog_app/app/__init__.py:48]
2020-08-03 00:08:26,725 INFO: Microblog Starting [in /Users/sadeliyi/Documents/Python Projects/microblog_app/app/__init__.py:48]
2020-08-05 16:42:24,840 INFO: Microblog Starting [in /Users/sadeliyi/Documents/Python Projects/microblog_app/app/__init__.py:50]
2020-08-10 21:39:14,528 INFO: Microblog Starting [in /Users/sadeliyi/Documents/Python Projects/microblog_app/app/__init__.py:50]
2020-08-10 22:38:52,679 INFO: Microblog Starting [in /Users/sadeliyi/Documents/Python Projects/microblog_app/app/__init__.py:50]
2020-08-10 22:45:14,461 INFO: Microblog Starting [in /Users/sadeliyi/Documents/Python Projects/microblog_app/app/__init__.py:50]
2020-08-10 22:52:46,006 INFO: Microblog Starting [in /Users/sadeliyi/Documents/Python Projects/microblog_app/app/__init__.py:50]
2020-08-14 00:15:02,747 INFO: Microblog Starting [in /Users/sadeliyi/Documents/Python Projects/microblog_app/app/__init__.py:52]
2020-08-14 00:15:10,928 ERROR: Exception on /index [GET] [in /Users/sadeliyi/Documents/Python Projects/microblog_app/venv/lib/python3.7/site-packages/flask/app.py:1892]
Traceback (most recent call last):
  File "/Users/sadeliyi/Documents/Python Projects/microblog_app/venv/lib/python3.7/site-packages/flask/app.py", line 2447, in wsgi_app
    response = self.full_dispatch_request()
  File "/Users/sadeliyi/Documents/Python Projects/microblog_app/venv/lib/python3.7/site-packages/flask/app.py", line 1952, in full_dispatch_request
    rv = self.handle_user_exception(e)
  File "/Users/sadeliyi/Documents/Python Projects/microblog_app/venv/lib/python3.7/site-packages/flask/app.py", line 1821, in handle_user_exception
    reraise(exc_type, exc_value, tb)
  File "/Users/sadeliyi/Documents/Python Projects/microblog_app/venv/lib/python3.7/site-packages/flask/_compat.py", line 39, in reraise
    raise value
  File "/Users/sadeliyi/Documents/Python Projects/microblog_app/venv/lib/python3.7/site-packages/flask/app.py", line 1950, in full_dispatch_request
    rv = self.dispatch_request()
  File "/Users/sadeliyi/Documents/Python Projects/microblog_app/venv/lib/python3.7/site-packages/flask/app.py", line 1936, in dispatch_request
    return self.view_functions[rule.endpoint](**req.view_args)
  File "/Users/sadeliyi/Documents/Python Projects/microblog_app/venv/lib/python3.7/site-packages/flask_login/utils.py", line 272, in decorated_view
    return func(*args, **kwargs)
  File "/Users/sadeliyi/Documents/Python Projects/microblog_app/app/routes.py", line 38, in index
    next_url=next_url, form=form)
  File "/Users/sadeliyi/Documents/Python Projects/microblog_app/venv/lib/python3.7/site-packages/flask/templating.py", line 140, in render_template
    ctx.app,
  File "/Users/sadeliyi/Documents/Python Projects/microblog_app/venv/lib/python3.7/site-packages/flask/templating.py", line 120, in _render
    rv = template.render(context)
  File "/Users/sadeliyi/Documents/Python Projects/microblog_app/venv/lib/python3.7/site-packages/jinja2/environment.py", line 1090, in render
    self.environment.handle_exception()
  File "/Users/sadeliyi/Documents/Python Projects/microblog_app/venv/lib/python3.7/site-packages/jinja2/environment.py", line 832, in handle_exception
    reraise(*rewrite_traceback_stack(source=source))
  File "/Users/sadeliyi/Documents/Python Projects/microblog_app/venv/lib/python3.7/site-packages/jinja2/_compat.py", line 28, in reraise
    raise value.with_traceback(tb)
  File "/Users/sadeliyi/Documents/Python Projects/microblog_app/app/templates/index.html", line 2, in top-level template code
    {% import 'bootstrap/wtf.html' as wtf %}
  File "/Users/sadeliyi/Documents/Python Projects/microblog_app/app/templates/base.html", line 2, in top-level template code
    {% extends 'bootstrap/base.html' %}
  File "/Users/sadeliyi/Documents/Python Projects/microblog_app/venv/lib/python3.7/site-packages/flask_bootstrap/templates/bootstrap/base.html", line 1, in top-level template code
    {% block doc -%}
  File "/Users/sadeliyi/Documents/Python Projects/microblog_app/venv/lib/python3.7/site-packages/flask_bootstrap/templates/bootstrap/base.html", line 4, in block "doc"
    {%- block html %}
  File "/Users/sadeliyi/Documents/Python Projects/microblog_app/venv/lib/python3.7/site-packages/flask_bootstrap/templates/bootstrap/base.html", line 20, in block "html"
    {% block body -%}
  File "/Users/sadeliyi/Documents/Python Projects/microblog_app/venv/lib/python3.7/site-packages/flask_bootstrap/templates/bootstrap/base.html", line 23, in block "body"
    {% block content -%}
  File "/Users/sadeliyi/Documents/Python Projects/microblog_app/app/templates/base.html", line 49, in block "content"
    {% block app_content %}{% endblock %}
  File "/Users/sadeliyi/Documents/Python Projects/microblog_app/app/templates/index.html", line 11, in block "app_content"
    {% include 'partials/_posts.html' %}
  File "/Users/sadeliyi/Documents/Python Projects/microblog_app/app/templates/partials/_posts.html", line 1, in top-level template code
    {% block scripts %}
  File "/Users/sadeliyi/Documents/Python Projects/microblog_app/app/templates/partials/_posts.html", line 3, in block "scripts"
    {{ super() }}
jinja2.exceptions.UndefinedError: there is no parent block called 'scripts'.
2020-08-14 00:15:46,203 ERROR: Exception on /index [GET] [in /Users/sadeliyi/Documents/Python Projects/microblog_app/venv/lib/python3.7/site-packages/flask/app.py:1892]
Traceback (most recent call last):
  File "/Users/sadeliyi/Documents/Python Projects/microblog_app/venv/lib/python3.7/site-packages/flask/app.py", line 2447, in wsgi_app
    response = self.full_dispatch_request()
  File "/Users/sadeliyi/Documents/Python Projects/microblog_app/venv/lib/python3.7/site-packages/flask/app.py", line 1952, in full_dispatch_request
    rv = self.handle_user_exception(e)
  File "/Users/sadeliyi/Documents/Python Projects/microblog_app/venv/lib/python3.7/site-packages/flask/app.py", line 1821, in handle_user_exception
    reraise(exc_type, exc_value, tb)
  File "/Users/sadeliyi/Documents/Python Projects/microblog_app/venv/lib/python3.7/site-packages/flask/_compat.py", line 39, in reraise
    raise value
  File "/Users/sadeliyi/Documents/Python Projects/microblog_app/venv/lib/python3.7/site-packages/flask/app.py", line 1950, in full_dispatch_request
    rv = self.dispatch_request()
  File "/Users/sadeliyi/Documents/Python Projects/microblog_app/venv/lib/python3.7/site-packages/flask/app.py", line 1936, in dispatch_request
    return self.view_functions[rule.endpoint](**req.view_args)
  File "/Users/sadeliyi/Documents/Python Projects/microblog_app/venv/lib/python3.7/site-packages/flask_login/utils.py", line 272, in decorated_view
    return func(*args, **kwargs)
  File "/Users/sadeliyi/Documents/Python Projects/microblog_app/app/routes.py", line 38, in index
    next_url=next_url, form=form)
  File "/Users/sadeliyi/Documents/Python Projects/microblog_app/venv/lib/python3.7/site-packages/flask/templating.py", line 140, in render_template
    ctx.app,
  File "/Users/sadeliyi/Documents/Python Projects/microblog_app/venv/lib/python3.7/site-packages/flask/templating.py", line 120, in _render
    rv = template.render(context)
  File "/Users/sadeliyi/Documents/Python Projects/microblog_app/venv/lib/python3.7/site-packages/jinja2/environment.py", line 1090, in render
    self.environment.handle_exception()
  File "/Users/sadeliyi/Documents/Python Projects/microblog_app/venv/lib/python3.7/site-packages/jinja2/environment.py", line 832, in handle_exception
    reraise(*rewrite_traceback_stack(source=source))
  File "/Users/sadeliyi/Documents/Python Projects/microblog_app/venv/lib/python3.7/site-packages/jinja2/_compat.py", line 28, in reraise
    raise value.with_traceback(tb)
  File "/Users/sadeliyi/Documents/Python Projects/microblog_app/app/templates/index.html", line 2, in top-level template code
    {% import 'bootstrap/wtf.html' as wtf %}
  File "/Users/sadeliyi/Documents/Python Projects/microblog_app/app/templates/base.html", line 2, in top-level template code
    {% extends 'bootstrap/base.html' %}
  File "/Users/sadeliyi/Documents/Python Projects/microblog_app/venv/lib/python3.7/site-packages/flask_bootstrap/templates/bootstrap/base.html", line 1, in top-level template code
    {% block doc -%}
  File "/Users/sadeliyi/Documents/Python Projects/microblog_app/venv/lib/python3.7/site-packages/flask_bootstrap/templates/bootstrap/base.html", line 4, in block "doc"
    {%- block html %}
  File "/Users/sadeliyi/Documents/Python Projects/microblog_app/venv/lib/python3.7/site-packages/flask_bootstrap/templates/bootstrap/base.html", line 20, in block "html"
    {% block body -%}
  File "/Users/sadeliyi/Documents/Python Projects/microblog_app/venv/lib/python3.7/site-packages/flask_bootstrap/templates/bootstrap/base.html", line 23, in block "body"
    {% block content -%}
  File "/Users/sadeliyi/Documents/Python Projects/microblog_app/app/templates/base.html", line 49, in block "content"
    {% block app_content %}{% endblock %}
  File "/Users/sadeliyi/Documents/Python Projects/microblog_app/app/templates/index.html", line 11, in block "app_content"
    {% include 'partials/_posts.html' %}
  File "/Users/sadeliyi/Documents/Python Projects/microblog_app/app/templates/partials/_posts.html", line 1, in top-level template code
    <table class="table table-hover">
  File "/Users/sadeliyi/Documents/Python Projects/microblog_app/app/templates/partials/_posts.html", line 3, in block "scripts"
    <td width="70px">
jinja2.exceptions.UndefinedError: there is no parent block called 'scripts'.
2020-08-14 00:15:53,951 INFO: Microblog Starting [in /Users/sadeliyi/Documents/Python Projects/microblog_app/app/__init__.py:52]
2020-08-14 00:23:08,950 INFO: Microblog Starting [in /Users/sadeliyi/Documents/Python Projects/microblog_app/app/__init__.py:52]
2020-08-20 00:54:43,652 INFO: Microblog Starting [in /Users/sadeliyi/Documents/Python Projects/microblog_app/app/__init__.py:61]
2020-08-20 01:20:36,836 INFO: Microblog Starting [in /Users/sadeliyi/Documents/Python Projects/microblog_app/app/__init__.py:60]
2020-08-20 02:05:09,746 INFO: Microblog Starting [in /Users/sadeliyi/Documents/Python Projects/microblog_app/app/__init__.py:60]
2020-08-20 02:05:16,105 INFO: Microblog Starting [in /Users/sadeliyi/Documents/Python Projects/microblog_app/app/__init__.py:60]
2020-08-20 02:05:32,983 INFO: Microblog Starting [in /Users/sadeliyi/Documents/Python Projects/microblog_app/app/__init__.py:60]
2020-08-22 19:41:13,433 INFO: Microblog Starting [in /Users/sadeliyi/Documents/Python Projects/microblog_app/app/__init__.py:60]
2020-08-22 19:41:20,296 INFO: Microblog Starting [in /Users/sadeliyi/Documents/Python Projects/microblog_app/app/__init__.py:60]
2020-08-27 01:05:58,826 INFO: Microblog Starting [in /Users/sadeliyi/Documents/Python Projects/microblog_app/app/__init__.py:60]
2020-08-27 01:08:38,723 INFO: Microblog Starting [in /Users/sadeliyi/Documents/Python Projects/microblog_app/app/__init__.py:60]
2020-08-27 02:01:23,403 INFO: Microblog Starting [in /Users/sadeliyi/Documents/Python Projects/microblog_app/app/__init__.py:60]
2020-08-27 02:51:49,838 INFO: Microblog Starting [in /Users/sadeliyi/Documents/Python Projects/microblog_app/app/__init__.py:60]
2020-08-27 03:07:50,800 INFO: Microblog Starting [in /Users/sadeliyi/Documents/Python Projects/microblog_app/app/__init__.py:60]
2020-08-27 03:11:39,869 INFO: Microblog Starting [in /Users/sadeliyi/Documents/Python Projects/microblog_app/app/__init__.py:60]
2020-08-28 15:47:34,611 INFO: Microblog Starting [in /Users/sadeliyi/Documents/Python Projects/microblog_app/app/__init__.py:60]
2020-08-28 15:49:17,852 INFO: Microblog Starting [in /Users/sadeliyi/Documents/Python Projects/microblog_app/app/__init__.py:60]
2020-08-28 15:53:12,767 INFO: Microblog Starting [in /Users/sadeliyi/Documents/Python Projects/microblog_app/app/__init__.py:60]
2020-08-29 15:35:50,527 INFO: Microblog Starting [in /Users/sadeliyi/Documents/Python Projects/microblog_app/app/__init__.py:60]
2020-08-29 15:42:58,003 INFO: Microblog Starting [in /Users/sadeliyi/Documents/Python Projects/microblog_app/app/__init__.py:60]
2020-08-29 16:10:49,653 INFO: Microblog Starting [in /Users/sadeliyi/Documents/Python Projects/microblog_app/app/__init__.py:60]
2020-08-29 16:10:58,244 INFO: Microblog Starting [in /Users/sadeliyi/Documents/Python Projects/microblog_app/app/__init__.py:60]
2020-08-29 16:22:41,530 INFO: Microblog Starting [in /Users/sadeliyi/Documents/Python Projects/microblog_app/app/__init__.py:60]
2020-08-29 16:30:38,728 INFO: Microblog Starting [in /Users/sadeliyi/Documents/Python Projects/microblog_app/app/__init__.py:60]
2020-08-30 16:26:52,663 INFO: Microblog Starting [in /Users/sadeliyi/Documents/Python Projects/microblog_app/app/__init__.py:60]
2020-08-30 16:33:15,470 INFO: Microblog Starting [in /Users/sadeliyi/Documents/Python Projects/microblog_app/app/__init__.py:60]
2020-08-30 16:35:29,209 INFO: Microblog Starting [in /Users/sadeliyi/Documents/Python Projects/microblog_app/app/__init__.py:60]
2020-08-30 16:50:27,752 INFO: Microblog Starting [in /Users/sadeliyi/Documents/Python Projects/microblog_app/app/__init__.py:60]
2020-08-30 17:09:04,273 INFO: Microblog Starting [in /Users/sadeliyi/Documents/Python Projects/microblog_app/app/__init__.py:60]
2020-08-30 17:10:34,871 INFO: Microblog Starting [in /Users/sadeliyi/Documents/Python Projects/microblog_app/app/__init__.py:60]
2020-08-30 17:17:25,834 INFO: Microblog Starting [in /Users/sadeliyi/Documents/Python Projects/microblog_app/app/__init__.py:60]
2020-08-30 17:29:43,502 INFO: Microblog Starting [in /Users/sadeliyi/Documents/Python Projects/microblog_app/app/__init__.py:60]
2020-08-30 17:32:01,523 INFO: Microblog Starting [in /Users/sadeliyi/Documents/Python Projects/microblog_app/app/__init__.py:60]
2020-08-30 17:38:58,820 INFO: Microblog Starting [in /Users/sadeliyi/Documents/Python Projects/microblog_app/app/__init__.py:60]
2020-08-30 17:39:09,392 ERROR: Exception on /translate [POST] [in /Users/sadeliyi/Documents/Python Projects/microblog_app/venv/lib/python3.7/site-packages/flask/app.py:1892]
Traceback (most recent call last):
  File "/Users/sadeliyi/Documents/Python Projects/microblog_app/venv/lib/python3.7/site-packages/flask/app.py", line 2447, in wsgi_app
    response = self.full_dispatch_request()
  File "/Users/sadeliyi/Documents/Python Projects/microblog_app/venv/lib/python3.7/site-packages/flask/app.py", line 1952, in full_dispatch_request
    rv = self.handle_user_exception(e)
  File "/Users/sadeliyi/Documents/Python Projects/microblog_app/venv/lib/python3.7/site-packages/flask/app.py", line 1821, in handle_user_exception
    reraise(exc_type, exc_value, tb)
  File "/Users/sadeliyi/Documents/Python Projects/microblog_app/venv/lib/python3.7/site-packages/flask/_compat.py", line 39, in reraise
    raise value
  File "/Users/sadeliyi/Documents/Python Projects/microblog_app/venv/lib/python3.7/site-packages/flask/app.py", line 1950, in full_dispatch_request
    rv = self.dispatch_request()
  File "/Users/sadeliyi/Documents/Python Projects/microblog_app/venv/lib/python3.7/site-packages/flask/app.py", line 1936, in dispatch_request
    return self.view_functions[rule.endpoint](**req.view_args)
  File "/Users/sadeliyi/Documents/Python Projects/microblog_app/venv/lib/python3.7/site-packages/flask_login/utils.py", line 272, in decorated_view
    return func(*args, **kwargs)
  File "/Users/sadeliyi/Documents/Python Projects/microblog_app/app/routes.py", line 211, in translate_text
    request.form['to_lang'])})
  File "/Users/sadeliyi/Documents/Python Projects/microblog_app/app/translate.py", line 27, in translate
    value = resp_obj.translations.text
AttributeError: 'list' object has no attribute 'translations'
2020-08-30 17:41:37,042 INFO: Microblog Starting [in /Users/sadeliyi/Documents/Python Projects/microblog_app/app/__init__.py:60]
2020-08-30 17:42:51,008 INFO: Microblog Starting [in /Users/sadeliyi/Documents/Python Projects/microblog_app/app/__init__.py:60]
2020-08-30 17:42:57,332 ERROR: Exception on /translate [POST] [in /Users/sadeliyi/Documents/Python Projects/microblog_app/venv/lib/python3.7/site-packages/flask/app.py:1892]
Traceback (most recent call last):
  File "/Users/sadeliyi/Documents/Python Projects/microblog_app/venv/lib/python3.7/site-packages/flask/app.py", line 2447, in wsgi_app
    response = self.full_dispatch_request()
  File "/Users/sadeliyi/Documents/Python Projects/microblog_app/venv/lib/python3.7/site-packages/flask/app.py", line 1952, in full_dispatch_request
    rv = self.handle_user_exception(e)
  File "/Users/sadeliyi/Documents/Python Projects/microblog_app/venv/lib/python3.7/site-packages/flask/app.py", line 1821, in handle_user_exception
    reraise(exc_type, exc_value, tb)
  File "/Users/sadeliyi/Documents/Python Projects/microblog_app/venv/lib/python3.7/site-packages/flask/_compat.py", line 39, in reraise
    raise value
  File "/Users/sadeliyi/Documents/Python Projects/microblog_app/venv/lib/python3.7/site-packages/flask/app.py", line 1950, in full_dispatch_request
    rv = self.dispatch_request()
  File "/Users/sadeliyi/Documents/Python Projects/microblog_app/venv/lib/python3.7/site-packages/flask/app.py", line 1936, in dispatch_request
    return self.view_functions[rule.endpoint](**req.view_args)
  File "/Users/sadeliyi/Documents/Python Projects/microblog_app/venv/lib/python3.7/site-packages/flask_login/utils.py", line 272, in decorated_view
    return func(*args, **kwargs)
  File "/Users/sadeliyi/Documents/Python Projects/microblog_app/app/routes.py", line 211, in translate_text
    request.form['to_lang'])})
  File "/Users/sadeliyi/Documents/Python Projects/microblog_app/app/translate.py", line 27, in translate
    value = resp_obj[0][0]['text']
KeyError: 0
2020-08-30 17:49:29,432 INFO: Microblog Starting [in /Users/sadeliyi/Documents/Python Projects/microblog_app/app/__init__.py:60]
2020-09-09 00:26:17,362 INFO: Microblog Starting [in /Users/sadeliyi/Documents/Python Projects/microblog_app/app/__init__.py:74]
2020-09-09 00:29:26,474 INFO: Microblog Starting [in /Users/sadeliyi/Documents/Python Projects/microblog_app/app/__init__.py:72]
2020-09-09 00:29:55,607 INFO: Microblog Starting [in /Users/sadeliyi/Documents/Python Projects/microblog_app/app/__init__.py:72]
2020-09-09 00:46:42,073 INFO: Microblog Starting [in /Users/sadeliyi/Documents/Python Projects/microblog_app/app/__init__.py:72]
2020-09-09 00:46:49,451 INFO: Microblog Starting [in /Users/sadeliyi/Documents/Python Projects/microblog_app/app/__init__.py:72]
2020-09-09 00:52:19,164 INFO: Microblog Starting [in /Users/sadeliyi/Documents/Python Projects/microblog_app/app/__init__.py:72]
2020-09-09 02:04:03,483 INFO: Microblog Starting [in /Users/sadeliyi/Documents/Python Projects/microblog_app/app/__init__.py:72]
2020-09-09 02:52:01,889 INFO: Microblog Starting [in /Users/sadeliyi/Documents/Python Projects/microblog_app/app/__init__.py:72]
2020-09-09 02:52:03,937 ERROR: Exception on / [GET] [in /Users/sadeliyi/Documents/Python Projects/microblog_app/venv/lib/python3.7/site-packages/flask/app.py:1892]
Traceback (most recent call last):
  File "/Users/sadeliyi/Documents/Python Projects/microblog_app/venv/lib/python3.7/site-packages/flask/app.py", line 2447, in wsgi_app
    response = self.full_dispatch_request()
  File "/Users/sadeliyi/Documents/Python Projects/microblog_app/venv/lib/python3.7/site-packages/flask/app.py", line 1952, in full_dispatch_request
    rv = self.handle_user_exception(e)
  File "/Users/sadeliyi/Documents/Python Projects/microblog_app/venv/lib/python3.7/site-packages/flask/app.py", line 1821, in handle_user_exception
    reraise(exc_type, exc_value, tb)
  File "/Users/sadeliyi/Documents/Python Projects/microblog_app/venv/lib/python3.7/site-packages/flask/_compat.py", line 39, in reraise
    raise value
  File "/Users/sadeliyi/Documents/Python Projects/microblog_app/venv/lib/python3.7/site-packages/flask/app.py", line 1950, in full_dispatch_request
    rv = self.dispatch_request()
  File "/Users/sadeliyi/Documents/Python Projects/microblog_app/venv/lib/python3.7/site-packages/flask/app.py", line 1936, in dispatch_request
    return self.view_functions[rule.endpoint](**req.view_args)
  File "/Users/sadeliyi/Documents/Python Projects/microblog_app/venv/lib/python3.7/site-packages/flask_login/utils.py", line 271, in decorated_view
    return current_app.login_manager.unauthorized()
  File "/Users/sadeliyi/Documents/Python Projects/microblog_app/venv/lib/python3.7/site-packages/flask_login/login_manager.py", line 174, in unauthorized
    redirect_url = make_login_url(login_view, next_url=request.url)
  File "/Users/sadeliyi/Documents/Python Projects/microblog_app/venv/lib/python3.7/site-packages/flask_login/utils.py", line 120, in login_url
    base = expand_login_view(login_view)
  File "/Users/sadeliyi/Documents/Python Projects/microblog_app/venv/lib/python3.7/site-packages/flask_login/utils.py", line 97, in expand_login_view
    return url_for(login_view)
  File "/Users/sadeliyi/Documents/Python Projects/microblog_app/venv/lib/python3.7/site-packages/flask/helpers.py", line 370, in url_for
    return appctx.app.handle_url_build_error(error, endpoint, values)
  File "/Users/sadeliyi/Documents/Python Projects/microblog_app/venv/lib/python3.7/site-packages/flask/app.py", line 2216, in handle_url_build_error
    reraise(exc_type, exc_value, tb)
  File "/Users/sadeliyi/Documents/Python Projects/microblog_app/venv/lib/python3.7/site-packages/flask/_compat.py", line 39, in reraise
    raise value
  File "/Users/sadeliyi/Documents/Python Projects/microblog_app/venv/lib/python3.7/site-packages/flask/helpers.py", line 358, in url_for
    endpoint, values, method=method, force_external=external
  File "/Users/sadeliyi/Documents/Python Projects/microblog_app/venv/lib/python3.7/site-packages/werkzeug/routing.py", line 2179, in build
    raise BuildError(endpoint, values, method, self)
werkzeug.routing.BuildError: Could not build url for endpoint 'login'. Did you mean 'auth.login' instead?
2020-09-09 02:52:05,066 ERROR: Exception on /favicon.ico [GET] [in /Users/sadeliyi/Documents/Python Projects/microblog_app/venv/lib/python3.7/site-packages/flask/app.py:1892]
Traceback (most recent call last):
  File "/Users/sadeliyi/Documents/Python Projects/microblog_app/venv/lib/python3.7/site-packages/flask/app.py", line 1950, in full_dispatch_request
    rv = self.dispatch_request()
  File "/Users/sadeliyi/Documents/Python Projects/microblog_app/venv/lib/python3.7/site-packages/flask/app.py", line 1926, in dispatch_request
    self.raise_routing_exception(req)
  File "/Users/sadeliyi/Documents/Python Projects/microblog_app/venv/lib/python3.7/site-packages/flask/app.py", line 1908, in raise_routing_exception
    raise request.routing_exception
  File "/Users/sadeliyi/Documents/Python Projects/microblog_app/venv/lib/python3.7/site-packages/flask/ctx.py", line 350, in match_request
    result = self.url_adapter.match(return_rule=True)
  File "/Users/sadeliyi/Documents/Python Projects/microblog_app/venv/lib/python3.7/site-packages/werkzeug/routing.py", line 1945, in match
    raise NotFound()
werkzeug.exceptions.NotFound: 404 Not Found: The requested URL was not found on the server. If you entered the URL manually please check your spelling and try again.

During handling of the above exception, another exception occurred:

Traceback (most recent call last):
  File "/Users/sadeliyi/Documents/Python Projects/microblog_app/venv/lib/python3.7/site-packages/flask/app.py", line 2447, in wsgi_app
    response = self.full_dispatch_request()
  File "/Users/sadeliyi/Documents/Python Projects/microblog_app/venv/lib/python3.7/site-packages/flask/app.py", line 1952, in full_dispatch_request
    rv = self.handle_user_exception(e)
  File "/Users/sadeliyi/Documents/Python Projects/microblog_app/venv/lib/python3.7/site-packages/flask/app.py", line 1816, in handle_user_exception
    return self.handle_http_exception(e)
  File "/Users/sadeliyi/Documents/Python Projects/microblog_app/venv/lib/python3.7/site-packages/flask/app.py", line 1744, in handle_http_exception
    return handler(e)
  File "/Users/sadeliyi/Documents/Python Projects/microblog_app/app/errors/handlers.py", line 7, in not_found_error
    return render_template('errors/404.html'), 404
  File "/Users/sadeliyi/Documents/Python Projects/microblog_app/venv/lib/python3.7/site-packages/flask/templating.py", line 140, in render_template
    ctx.app,
  File "/Users/sadeliyi/Documents/Python Projects/microblog_app/venv/lib/python3.7/site-packages/flask/templating.py", line 120, in _render
    rv = template.render(context)
  File "/Users/sadeliyi/Documents/Python Projects/microblog_app/venv/lib/python3.7/site-packages/jinja2/environment.py", line 1090, in render
    self.environment.handle_exception()
  File "/Users/sadeliyi/Documents/Python Projects/microblog_app/venv/lib/python3.7/site-packages/jinja2/environment.py", line 832, in handle_exception
    reraise(*rewrite_traceback_stack(source=source))
  File "/Users/sadeliyi/Documents/Python Projects/microblog_app/venv/lib/python3.7/site-packages/jinja2/_compat.py", line 28, in reraise
    raise value.with_traceback(tb)
  File "/Users/sadeliyi/Documents/Python Projects/microblog_app/app/templates/errors/404.html", line 1, in top-level template code
    {% extends 'main/base.html' %}
  File "/Users/sadeliyi/Documents/Python Projects/microblog_app/app/templates/main/base.html", line 2, in top-level template code
    {% extends 'bootstrap/base.html' %}
  File "/Users/sadeliyi/Documents/Python Projects/microblog_app/venv/lib/python3.7/site-packages/flask_bootstrap/templates/bootstrap/base.html", line 1, in top-level template code
    {% block doc -%}
  File "/Users/sadeliyi/Documents/Python Projects/microblog_app/venv/lib/python3.7/site-packages/flask_bootstrap/templates/bootstrap/base.html", line 4, in block "doc"
    {%- block html %}
  File "/Users/sadeliyi/Documents/Python Projects/microblog_app/venv/lib/python3.7/site-packages/flask_bootstrap/templates/bootstrap/base.html", line 20, in block "html"
    {% block body -%}
  File "/Users/sadeliyi/Documents/Python Projects/microblog_app/venv/lib/python3.7/site-packages/flask_bootstrap/templates/bootstrap/base.html", line 21, in block "body"
    {% block navbar %}
  File "/Users/sadeliyi/Documents/Python Projects/microblog_app/app/templates/main/base.html", line 18, in block "navbar"
    <a class="navbar-brand" href="{{ url_for('index') }}">Microblog</a>
  File "/Users/sadeliyi/Documents/Python Projects/microblog_app/venv/lib/python3.7/site-packages/flask/helpers.py", line 370, in url_for
    return appctx.app.handle_url_build_error(error, endpoint, values)
  File "/Users/sadeliyi/Documents/Python Projects/microblog_app/venv/lib/python3.7/site-packages/flask/app.py", line 2216, in handle_url_build_error
    reraise(exc_type, exc_value, tb)
  File "/Users/sadeliyi/Documents/Python Projects/microblog_app/venv/lib/python3.7/site-packages/flask/_compat.py", line 39, in reraise
    raise value
  File "/Users/sadeliyi/Documents/Python Projects/microblog_app/venv/lib/python3.7/site-packages/flask/helpers.py", line 358, in url_for
    endpoint, values, method=method, force_external=external
  File "/Users/sadeliyi/Documents/Python Projects/microblog_app/venv/lib/python3.7/site-packages/werkzeug/routing.py", line 2179, in build
    raise BuildError(endpoint, values, method, self)
werkzeug.routing.BuildError: Could not build url for endpoint 'index'. Did you mean 'main.index' instead?
2020-09-09 02:57:02,650 INFO: Microblog Starting [in /Users/sadeliyi/Documents/Python Projects/microblog_app/app/__init__.py:72]
2020-09-09 02:57:04,082 ERROR: Exception on / [GET] [in /Users/sadeliyi/Documents/Python Projects/microblog_app/venv/lib/python3.7/site-packages/flask/app.py:1892]
Traceback (most recent call last):
  File "/Users/sadeliyi/Documents/Python Projects/microblog_app/venv/lib/python3.7/site-packages/flask/app.py", line 2447, in wsgi_app
    response = self.full_dispatch_request()
  File "/Users/sadeliyi/Documents/Python Projects/microblog_app/venv/lib/python3.7/site-packages/flask/app.py", line 1952, in full_dispatch_request
    rv = self.handle_user_exception(e)
  File "/Users/sadeliyi/Documents/Python Projects/microblog_app/venv/lib/python3.7/site-packages/flask/app.py", line 1821, in handle_user_exception
    reraise(exc_type, exc_value, tb)
  File "/Users/sadeliyi/Documents/Python Projects/microblog_app/venv/lib/python3.7/site-packages/flask/_compat.py", line 39, in reraise
    raise value
  File "/Users/sadeliyi/Documents/Python Projects/microblog_app/venv/lib/python3.7/site-packages/flask/app.py", line 1950, in full_dispatch_request
    rv = self.dispatch_request()
  File "/Users/sadeliyi/Documents/Python Projects/microblog_app/venv/lib/python3.7/site-packages/flask/app.py", line 1936, in dispatch_request
    return self.view_functions[rule.endpoint](**req.view_args)
  File "/Users/sadeliyi/Documents/Python Projects/microblog_app/venv/lib/python3.7/site-packages/flask_login/utils.py", line 271, in decorated_view
    return current_app.login_manager.unauthorized()
  File "/Users/sadeliyi/Documents/Python Projects/microblog_app/venv/lib/python3.7/site-packages/flask_login/login_manager.py", line 174, in unauthorized
    redirect_url = make_login_url(login_view, next_url=request.url)
  File "/Users/sadeliyi/Documents/Python Projects/microblog_app/venv/lib/python3.7/site-packages/flask_login/utils.py", line 120, in login_url
    base = expand_login_view(login_view)
  File "/Users/sadeliyi/Documents/Python Projects/microblog_app/venv/lib/python3.7/site-packages/flask_login/utils.py", line 97, in expand_login_view
    return url_for(login_view)
  File "/Users/sadeliyi/Documents/Python Projects/microblog_app/venv/lib/python3.7/site-packages/flask/helpers.py", line 370, in url_for
    return appctx.app.handle_url_build_error(error, endpoint, values)
  File "/Users/sadeliyi/Documents/Python Projects/microblog_app/venv/lib/python3.7/site-packages/flask/app.py", line 2216, in handle_url_build_error
    reraise(exc_type, exc_value, tb)
  File "/Users/sadeliyi/Documents/Python Projects/microblog_app/venv/lib/python3.7/site-packages/flask/_compat.py", line 39, in reraise
    raise value
  File "/Users/sadeliyi/Documents/Python Projects/microblog_app/venv/lib/python3.7/site-packages/flask/helpers.py", line 358, in url_for
    endpoint, values, method=method, force_external=external
  File "/Users/sadeliyi/Documents/Python Projects/microblog_app/venv/lib/python3.7/site-packages/werkzeug/routing.py", line 2179, in build
    raise BuildError(endpoint, values, method, self)
werkzeug.routing.BuildError: Could not build url for endpoint 'login'. Did you mean 'auth.login' instead?
2020-09-09 03:00:56,881 ERROR: Exception on /index [GET] [in /Users/sadeliyi/Documents/Python Projects/microblog_app/venv/lib/python3.7/site-packages/flask/app.py:1892]
Traceback (most recent call last):
  File "/Users/sadeliyi/Documents/Python Projects/microblog_app/venv/lib/python3.7/site-packages/flask/app.py", line 2447, in wsgi_app
    response = self.full_dispatch_request()
  File "/Users/sadeliyi/Documents/Python Projects/microblog_app/venv/lib/python3.7/site-packages/flask/app.py", line 1952, in full_dispatch_request
    rv = self.handle_user_exception(e)
  File "/Users/sadeliyi/Documents/Python Projects/microblog_app/venv/lib/python3.7/site-packages/flask/app.py", line 1821, in handle_user_exception
    reraise(exc_type, exc_value, tb)
  File "/Users/sadeliyi/Documents/Python Projects/microblog_app/venv/lib/python3.7/site-packages/flask/_compat.py", line 39, in reraise
    raise value
  File "/Users/sadeliyi/Documents/Python Projects/microblog_app/venv/lib/python3.7/site-packages/flask/app.py", line 1950, in full_dispatch_request
    rv = self.dispatch_request()
  File "/Users/sadeliyi/Documents/Python Projects/microblog_app/venv/lib/python3.7/site-packages/flask/app.py", line 1936, in dispatch_request
    return self.view_functions[rule.endpoint](**req.view_args)
  File "/Users/sadeliyi/Documents/Python Projects/microblog_app/venv/lib/python3.7/site-packages/flask_login/utils.py", line 271, in decorated_view
    return current_app.login_manager.unauthorized()
  File "/Users/sadeliyi/Documents/Python Projects/microblog_app/venv/lib/python3.7/site-packages/flask_login/login_manager.py", line 174, in unauthorized
    redirect_url = make_login_url(login_view, next_url=request.url)
  File "/Users/sadeliyi/Documents/Python Projects/microblog_app/venv/lib/python3.7/site-packages/flask_login/utils.py", line 120, in login_url
    base = expand_login_view(login_view)
  File "/Users/sadeliyi/Documents/Python Projects/microblog_app/venv/lib/python3.7/site-packages/flask_login/utils.py", line 97, in expand_login_view
    return url_for(login_view)
  File "/Users/sadeliyi/Documents/Python Projects/microblog_app/venv/lib/python3.7/site-packages/flask/helpers.py", line 370, in url_for
    return appctx.app.handle_url_build_error(error, endpoint, values)
  File "/Users/sadeliyi/Documents/Python Projects/microblog_app/venv/lib/python3.7/site-packages/flask/app.py", line 2216, in handle_url_build_error
    reraise(exc_type, exc_value, tb)
  File "/Users/sadeliyi/Documents/Python Projects/microblog_app/venv/lib/python3.7/site-packages/flask/_compat.py", line 39, in reraise
    raise value
  File "/Users/sadeliyi/Documents/Python Projects/microblog_app/venv/lib/python3.7/site-packages/flask/helpers.py", line 358, in url_for
    endpoint, values, method=method, force_external=external
  File "/Users/sadeliyi/Documents/Python Projects/microblog_app/venv/lib/python3.7/site-packages/werkzeug/routing.py", line 2179, in build
    raise BuildError(endpoint, values, method, self)
werkzeug.routing.BuildError: Could not build url for endpoint 'login'. Did you mean 'auth.login' instead?
2020-09-09 03:01:17,995 ERROR: Exception on /index [GET] [in /Users/sadeliyi/Documents/Python Projects/microblog_app/venv/lib/python3.7/site-packages/flask/app.py:1892]
Traceback (most recent call last):
  File "/Users/sadeliyi/Documents/Python Projects/microblog_app/venv/lib/python3.7/site-packages/flask/app.py", line 2447, in wsgi_app
    response = self.full_dispatch_request()
  File "/Users/sadeliyi/Documents/Python Projects/microblog_app/venv/lib/python3.7/site-packages/flask/app.py", line 1952, in full_dispatch_request
    rv = self.handle_user_exception(e)
  File "/Users/sadeliyi/Documents/Python Projects/microblog_app/venv/lib/python3.7/site-packages/flask/app.py", line 1821, in handle_user_exception
    reraise(exc_type, exc_value, tb)
  File "/Users/sadeliyi/Documents/Python Projects/microblog_app/venv/lib/python3.7/site-packages/flask/_compat.py", line 39, in reraise
    raise value
  File "/Users/sadeliyi/Documents/Python Projects/microblog_app/venv/lib/python3.7/site-packages/flask/app.py", line 1950, in full_dispatch_request
    rv = self.dispatch_request()
  File "/Users/sadeliyi/Documents/Python Projects/microblog_app/venv/lib/python3.7/site-packages/flask/app.py", line 1936, in dispatch_request
    return self.view_functions[rule.endpoint](**req.view_args)
  File "/Users/sadeliyi/Documents/Python Projects/microblog_app/venv/lib/python3.7/site-packages/flask_login/utils.py", line 271, in decorated_view
    return current_app.login_manager.unauthorized()
  File "/Users/sadeliyi/Documents/Python Projects/microblog_app/venv/lib/python3.7/site-packages/flask_login/login_manager.py", line 174, in unauthorized
    redirect_url = make_login_url(login_view, next_url=request.url)
  File "/Users/sadeliyi/Documents/Python Projects/microblog_app/venv/lib/python3.7/site-packages/flask_login/utils.py", line 120, in login_url
    base = expand_login_view(login_view)
  File "/Users/sadeliyi/Documents/Python Projects/microblog_app/venv/lib/python3.7/site-packages/flask_login/utils.py", line 97, in expand_login_view
    return url_for(login_view)
  File "/Users/sadeliyi/Documents/Python Projects/microblog_app/venv/lib/python3.7/site-packages/flask/helpers.py", line 370, in url_for
    return appctx.app.handle_url_build_error(error, endpoint, values)
  File "/Users/sadeliyi/Documents/Python Projects/microblog_app/venv/lib/python3.7/site-packages/flask/app.py", line 2216, in handle_url_build_error
    reraise(exc_type, exc_value, tb)
  File "/Users/sadeliyi/Documents/Python Projects/microblog_app/venv/lib/python3.7/site-packages/flask/_compat.py", line 39, in reraise
    raise value
  File "/Users/sadeliyi/Documents/Python Projects/microblog_app/venv/lib/python3.7/site-packages/flask/helpers.py", line 358, in url_for
    endpoint, values, method=method, force_external=external
  File "/Users/sadeliyi/Documents/Python Projects/microblog_app/venv/lib/python3.7/site-packages/werkzeug/routing.py", line 2179, in build
    raise BuildError(endpoint, values, method, self)
werkzeug.routing.BuildError: Could not build url for endpoint 'login'. Did you mean 'auth.login' instead?
2020-09-09 03:12:41,674 INFO: Microblog Starting [in /Users/sadeliyi/Documents/Python Projects/microblog_app/app/__init__.py:72]
2020-09-15 00:22:38,161 INFO: Microblog Starting [in /Users/sadeliyi/Documents/Python Projects/microblog_app/app/__init__.py:75]
2020-09-15 00:38:47,932 INFO: Microblog Starting [in /Users/sadeliyi/Documents/Python Projects/microblog_app/app/__init__.py:75]
2020-09-15 00:46:32,691 INFO: Microblog Starting [in /Users/sadeliyi/Documents/Python Projects/microblog_app/app/__init__.py:75]
2020-09-15 01:07:05,910 INFO: Microblog Starting [in /Users/sadeliyi/Documents/Python Projects/microblog_app/app/__init__.py:75]
2020-09-15 01:11:26,129 INFO: Microblog Starting [in /Users/sadeliyi/Documents/Python Projects/microblog_app/app/__init__.py:75]
2020-09-15 01:19:32,387 INFO: Microblog Starting [in /Users/sadeliyi/Documents/Python Projects/microblog_app/app/__init__.py:75]
2020-09-15 01:38:30,930 INFO: Microblog Starting [in /Users/sadeliyi/Documents/Python Projects/microblog_app/app/__init__.py:75]
2020-09-15 01:44:32,166 INFO: Microblog Starting [in /Users/sadeliyi/Documents/Python Projects/microblog_app/app/__init__.py:75]
2020-09-18 00:32:04,567 INFO: Microblog Starting [in /Users/sadeliyi/Documents/Python Projects/microblog_app/app/__init__.py:74]
2020-09-18 00:54:56,330 INFO: Microblog Starting [in /Users/sadeliyi/Documents/Python Projects/microblog_app/app/__init__.py:74]
2020-09-22 01:14:00,496 INFO: Microblog Starting [in /Users/sadeliyi/Documents/Python Projects/microblog_app/app/__init__.py:74]
2020-09-22 01:16:17,076 INFO: Microblog Starting [in /Users/sadeliyi/Documents/Python Projects/microblog_app/app/__init__.py:74]
2020-09-22 01:18:28,541 INFO: Microblog Starting [in /Users/sadeliyi/Documents/Python Projects/microblog_app/app/__init__.py:74]
